Workbook

Sheet Delay
A1: Configuration | B1: Packet Size | C1: Devices | D1: CLAVES | E1: Mean H | F1: Std H | G1: Mean M | H1: Std M | I1: Mean L | J1: Std L | K1: Mean NRT | L1: Std NRT
A2: NO SDWN | B2: 256 | C2: 10 | D2: =A2&B2&C2 -> NO SDWN25610 | E2: 0.19976 | F2: 0.08023 | G2: 0.16788 | H2: 0.0711 | I2: 0.20745 | J2: 0.08156 | K2: 0.18146 | L2: 0.0757
A3: NO SDWN | B3: 256 | C3: 20 | D3: =A3&B3&C3 -> NO SDWN25620 | E3: 0.22666 | F3: 0.09756 | G3: 0.18668 | H3: 0.09043 | I3: 0.16038 | J3: 0.07292 | K3: 0.18505 | L3: 0.08867
A4: NO SDWN | B4: 256 | C4: 30 | D4: =A4&B4&C4 -> NO SDWN25630 | E4: 0.24792 | F4: 0.11649 | G4: 0.1987 | H4: 0.08313 | I4: 0.16873 | J4: 0.07926 | K4: 0.17811 | L4: 0.08205
A5: NO SDWN | B5: 256 | C5: 40 | D5: =A5&B5&C5 -> NO SDWN25640 | E5: 0.28039 | F5: 0.12411 | G5: 0.20848 | H5: 0.10981 | I5: 0.19812 | J5: 0.10088 | K5: 0.18802 | L5: 0.08467
A6: NO SDWN | B6: 256 | C6: 50 | D6: =A6&B6&C6 -> NO SDWN25650 | E6: 0.76274 | F6: 0.40667 | G6: 0.20378 | H6: 0.11496 | I6: 0.20503 | J6: 0.10937 | K6: 0.67477 | L6: 0.3498
A7: NO SDWN | B7: 256 | C7: 60 | D7: =A7&B7&C7 -> NO SDWN25660 | E7: 0.9394 | F7: 0.3376 | G7: 0.45998 | H7: 0.40486 | I7: 0.39169 | J7: 0.33197 | K7: 0.8096 | L7: 0.30415
A8: NO SDWN | B8: 256 | C8: 70 | D8: =A8&B8&C8 -> NO SDWN25670 | E8: 0.9477 | F8: 0.36974 | G8: 0.67734 | H8: 0.45047 | I8: 0.65318 | J8: 0.36205 | K8: 0.86462 | L8: 0.33095
A9: NO SDWN | B9: 256 | C9: 80 | D9: =A9&B9&C9 -> NO SDWN25680 | E9: 1.03022 | F9: 0.38803 | G9: 0.85127 | H9: 0.33724 | I9: 0.84142 | J9: 0.35679 | K9: 0.88014 | L9: 0.33984
A10: NO SDWN | B10: 256 | C10: 90 | D10: =A10&B10&C10 -> NO SDWN25690 | E10: 1.3124 | F10: 0.58814 | G10: 1.09418 | H10: 0.48603 | I10: 0.97032 | J10: 0.44486 | K10: 1.16632 | L10: 0.54327
A11: NO SDWN | B11: 256 | C11: 100 | D11: =A11&B11&C11 -> NO SDWN256100 | E11: 1.60007 | F11: 0.64636 | G11: 1.18289 | H11: 0.52694 | I11: 1.16571 | J11: 0.54222 | K11: 1.38556 | L11: 0.53537
A12: NO SDWN | B12: 512 | C12: 10 | D12: =A12&B12&C12 -> NO SDWN51210 | E12: 0.24675 | F12: 0.08096 | G12: 0.2212 | H12: 0.08519 | I12: 0.25543 | J12: 0.09266 | K12: 0.23794 | L12: 0.09244
A13: NO SDWN | B13: 512 | C13: 20 | D13: =A13&B13&C13 -> NO SDWN51220 | E13: 0.26765 | F13: 0.09237 | G13: 0.23687 | H13: 0.10018 | I13: 0.20876 | J13: 0.08882 | K13: 0.23505 | L13: 0.09936
... A121: SDWN IA | B121: 1024 | C121: 100 | D121: =A121&B121&C121 -> SDWN IA1024100 | E121: 1.72074 | F121: 0.67238 | G121: 0.80067 | H121: 0.32378 | I121: 1.62355 | J121: 0.7415 | K121: 1.7129 | L121: 0.68465

Sheet Throughput
A1: Configuration | B1: Packet Size | C1: Devices | D1: CLAVES | E1: Mean H | F1: Std H | G1: Mean M | H1: Std M | I1: Mean L | J1: Std L | K1: Mean NRT | L1: Std NRT
A2: NO SDWN | B2: 256 | C2: 10 | D2: =A2&B2&C2 -> NO SDWN25610 | E2: 2.27933 | F2: 0.00254 | G2: 2.27967 | H2: 0.00183 | I2: 2.2785 | J2: 0.00366 | K2: 2.2785 | L2: 0.00366
A3: NO SDWN | B3: 256 | C3: 20 | D3: =A3&B3&C3 -> NO SDWN25620 | E3: 2.278 | F3: 0.00404 | G3: 2.2786 | H3: 0.00351 | I3: 2.2794 | J3: 0.0024 | K3: 2.2796 | L3: 0.00198
A4: NO SDWN | B4: 256 | C4: 30 | D4: =A4&B4&C4 -> NO SDWN25630 | E4: 2.27588 | F4: 0.00495 | G4: 2.2785 | H4: 0.00359 | I4: 2.27929 | J4: 0.00259 | K4: 2.27914 | L4: 0.00282
A5: NO SDWN | B5: 256 | C5: 40 | D5: =A5&B5&C5 -> NO SDWN25640 | E5: 2.275 | F5: 0.00503 | G5: 2.2774 | H5: 0.00441 | I5: 2.278 | J5: 0.00402 | K5: 2.2791 | L5: 0.00288
A6: NO SDWN | B6: 256 | C6: 50 | D6: =A6&B6&C6 -> NO SDWN25650 | E6: 2.2745 | F6: 0.00515 | G6: 2.27727 | H6: 0.00481 | I6: 2.27758 | J6: 0.0043 | K6: 2.2785 | L6: 0.00359
A7: NO SDWN | B7: 256 | C7: 60 | D7: =A7&B7&C7 -> NO SDWN25660 | E7: 2.27416 | F7: 0.00534 | G7: 2.27604 | H7: 0.00504 | I7: 2.27813 | J7: 0.00391 | K7: 2.27799 | L7: 0.00402
A8: NO SDWN | B8: 256 | C8: 70 | D8: =A8&B8&C8 -> NO SDWN25670 | E8: 2.27376 | F8: 0.00591 | G8: 2.27561 | H8: 0.0053 | I8: 2.27714 | J8: 0.00466 | K8: 2.2778 | L8: 0.00444
A9: NO SDWN | B9: 256 | C9: 80 | D9: =A9&B9&C9 -> NO SDWN25680 | E9: 2.27136 | F9: 0.00666 | G9: 2.27595 | H9: 0.00502 | I9: 2.2767 | J9: 0.00493 | K9: 2.27785 | L9: 0.00412
A10: NO SDWN | B10: 256 | C10: 90 | D10: =A10&B10&C10 -> NO SDWN25690 | E10: 2.27202 | F10: 0.00692 | G10: 2.27463 | H10: 0.00597 | I10: 2.2768 | J10: 0.00477 | K10: 2.27809 | L10: 0.00394
A11: NO SDWN | B11: 256 | C11: 100 | D11: =A11&B11&C11 -> NO SDWN256100 | E11: 2.27093 | F11: 0.00804 | G11: 2.27403 | H11: 0.00629 | I11: 2.27603 | J11: 0.00574 | K11: 2.27785 | L11: 0.00411
A12: NO SDWN | B12: 512 | C12: 10 | D12: =A12&B12&C12 -> NO SDWN51210 | E12: 4.32933 | F12: 0.00254 | G12: 4.32967 | H12: 0.00183 | I12: 4.3285 | J12: 0.00366 | K12: 4.3285 | L12: 0.00366
A13: NO SDWN | B13: 512 | C13: 20 | D13: =A13&B13&C13 -> NO SDWN51220 | E13: 4.328 | F13: 0.00404 | G13: 4.3286 | H13: 0.00351 | I13: 4.3294 | J13: 0.0024 | K13: 4.3296 | L13: 0.00198
... A121: SDWN IA | B121: 1024 | C121: 100 | D121: =A121&B121&C121 -> SDWN IA1024100 | E121: 8.42328 | F121: 0.00839 | G121: 8.42836 | H121: 0.00402 | I121: 8.42956 | J121: 0.00206 | K121: 8.42992 | L121: 0.00089

Sheet LostPackets
A1: Configuration | B1: Packet Size | C1: Devices | D1: CLAVES | E1: Mean H | F1: Std H | G1: Mean M | H1: Std M | I1: Mean L | J1: Std L | K1: Mean NRT | L1: Std NRT
A2: NO SDWN | B2: 256 | C2: 10 | D2: =A2&B2&C2 -> NO SDWN25610 | E2: 0.01111 | F2: 0.04157 | G2: 0.00556 | H2: 0.02992 | I2: 0.025 | J2: 0.05951 | K2: 0.025 | L2: 0.05951
A3: NO SDWN | B3: 256 | C3: 20 | D3: =A3&B3&C3 -> NO SDWN25620 | E3: 0.03333 | F3: 0.06667 | G3: 0.02333 | H3: 0.05783 | I3: 0.01 | J3: 0.03958 | K3: 0.00667 | L3: 0.03266
A4: NO SDWN | B4: 256 | C4: 30 | D4: =A4&B4&C4 -> NO SDWN25630 | E4: 0.07083 | F4: 0.0865 | G4: 0.025 | H4: 0.05951 | I4: 0.0119 | J4: 0.04292 | K4: 0.01429 | L4: 0.04666
A5: NO SDWN | B5: 256 | C5: 40 | D5: =A5&B5&C5 -> NO SDWN25640 | E5: 0.10333 | F5: 0.11494 | G5: 0.055 | H5: 0.10015 | I5: 0.035 | J5: 0.07186 | K5: 0.01667 | L5: 0.05528
A6: NO SDWN | B6: 256 | C6: 50 | D6: =A6&B6&C6 -> NO SDWN25650 | E6: 0.10724 | F6: 0.11137 | G6: 0.05469 | H6: 0.10439 | I6: 0.04722 | J6: 0.08919 | K6: 0.02778 | L6: 0.06917
A7: NO SDWN | B7: 256 | C7: 60 | D7: =A7&B7&C7 -> NO SDWN25660 | E7: 0.13087 | F7: 0.13456 | G7: 0.07942 | H7: 0.11022 | I7: 0.04222 | J7: 0.09465 | K7: 0.03579 | L7: 0.07369
A8: NO SDWN | B8: 256 | C8: 70 | D8: =A8&B8&C8 -> NO SDWN25670 | E8: 0.147 | F8: 0.15326 | G8: 0.10463 | H8: 0.13725 | I8: 0.0625 | J8: 0.11015 | K8: 0.04464 | L8: 0.09703
A9: NO SDWN | B9: 256 | C9: 80 | D9: =A9&B9&C9 -> NO SDWN25680 | E9: 0.21633 | F9: 0.1848 | G9: 0.095 | H9: 0.12857 | I9: 0.06937 | J9: 0.11257 | K9: 0.0425 | L9: 0.0866
A10: NO SDWN | B10: 256 | C10: 90 | D10: =A10&B10&C10 -> NO SDWN25690 | E10: 0.2076 | F10: 0.19062 | G10: 0.12849 | H10: 0.15411 | I10: 0.07002 | J10: 0.11338 | K10: 0.04015 | L10: 0.08864
A11: NO SDWN | B11: 256 | C11: 100 | D11: =A11&B11&C11 -> NO SDWN256100 | E11: 0.24157 | F11: 0.25343 | G11: 0.14382 | H11: 0.16577 | I11: 0.09649 | J11: 0.14779 | K11: 0.04791 | L11: 0.09868
A12: NO SDWN | B12: 512 | C12: 10 | D12: =A12&B12&C12 -> NO SDWN51210 | E12: 0.01111 | F12: 0.04157 | G12: 0.00556 | H12: 0.02992 | I12: 0.025 | J12: 0.05951 | K12: 0.025 | L12: 0.05951
A13: NO SDWN | B13: 512 | C13: 20 | D13: =A13&B13&C13 -> NO SDWN51220 | E13: 0.03333 | F13: 0.06667 | G13: 0.02333 | H13: 0.05783 | I13: 0.01 | J13: 0.03958 | K13: 0.00667 | L13: 0.03266
... A121: SDWN IA | B121: 1024 | C121: 100 | D121: =A121&B121&C121 -> SDWN IA1024100 | E121: 0.09867 | F121: 0.10561 | G121: 0.02667 | H121: 0.06289 | I121: 0.00733 | J121: 0.03418 | K121: 0.00133 | L121: 0.01485

Sheet Resumen Delay
A1: Packet Size | B1: Total Devices | D1: Netwoks Config. | E1: HIGH | G1: MEDIUM | I1: LOW | K1: NRT
E2: Mean | F2: +e(95%) | G2: Mean | H2: +e(95%) | I2: Mean | J2: +e(95%) | K2: Mean | L2: +e(95%) | M2: CLAVES
A3: 256 | B3: 10 | C3: \multirow{4}{*}{10} | D3: NO SDWN | E3: =IFERROR(VLOOKUP($M3, Delay!$D$2:$L$200, 2, 0),0) -> 0.19976 | F3: =IFERROR(VLOOKUP($M3, Delay!$D$2:$L$200, 3, 0),0)*2.262 /SQRT(10) -> 0.057389097 | G3: =IFERROR(VLOOKUP($M3, Delay!$D$2:$L$200, 4, 0),0) -> 0.16788 | H3: =IFERROR(VLOOKUP($M3, Delay!$D$2:$L$200, 5, 0),0)*2.262 /SQRT(10) -> 0.050858342 | I3: =IFERROR(VLOOKUP($M3, Delay!$D$2:$L$200, 6, 0),0) -> 0.20745 | J3: =IFERROR(VLOOKUP($M3, Delay!$D$2:$L$200, 7, 0),0)*2.262 /SQRT(10) -> 0.058340456 | K3: =IFERROR(VLOOKUP($M3, Delay!$D$2:$L$200, 8, 0),0) -> 0.18146 | L3: =IFERROR(VLOOKUP($M3, Delay!$D$2:$L$200, 9, 0),0)*2.262 /SQRT(10) -> 0.054148756 | M3: =D3&A3&B3 -> NO SDWN25610
A4: 256 | B4: 10 | D4: SDWN EDCA | E4: =IFERROR(VLOOKUP($M4, Delay!$D$2:$L$200, 2, 0),0) -> 0.1624 | F4: =IFERROR(VLOOKUP($M4, Delay!$D$2:$L$200, 3, 0),0)*2.262 /SQRT(10) -> 0.038676661 | G4: =IFERROR(VLOOKUP($M4, Delay!$D$2:$L$200, 4, 0),0) -> 0.14267 | H4: =IFERROR(VLOOKUP($M4, Delay!$D$2:$L$200, 5, 0),0)*2.262 /SQRT(10) -> 0.031087251 | I4: =IFERROR(VLOOKUP($M4, Delay!$D$2:$L$200, 6, 0),0) -> 0.20413 | J4: =IFERROR(VLOOKUP($M4, Delay!$D$2:$L$200, 7, 0),0)*2.262 /SQRT(10) -> 0.053755337 | K4: =IFERROR(VLOOKUP($M4, Delay!$D$2:$L$200, 8, 0),0) -> 0.181 | L4: =IFERROR(VLOOKUP($M4, Delay!$D$2:$L$200, 9, 0),0)*2.262 /SQRT(10) -> 0.060643745 | M4: =D4&A4&B4 -> SDWN EDCA25610
A5: 256 | B5: 10 | D5: SDWN MOD | E5: =IFERROR(VLOOKUP($M5, Delay!$D$2:$L$200, 2, 0),0) -> 0.21486 | F5: =IFERROR(VLOOKUP($M5, Delay!$D$2:$L$200, 3, 0),0)*2.262 /SQRT(10) -> 0.065228864 | G5: =IFERROR(VLOOKUP($M5, Delay!$D$2:$L$200, 4, 0),0) -> 0.17467 | H5: =IFERROR(VLOOKUP($M5, Delay!$D$2:$L$200, 5, 0),0)*2.262 /SQRT(10) -> 0.057525006 | I5: =IFERROR(VLOOKUP($M5, Delay!$D$2:$L$200, 6, 0),0) -> 0.20322 | J5: =IFERROR(VLOOKUP($M5, Delay!$D$2:$L$200, 7, 0),0)*2.262 /SQRT(10) -> 0.054213133 | K5: =IFERROR(VLOOKUP($M5, Delay!$D$2:$L$200, 8, 0),0) -> 0.1885 | L5: =IFERROR(VLOOKUP($M5, Delay!$D$2:$L$200, 9, 0),0)*2.262 /SQRT(10) -> 0.065979937 | M5: =D5&A5&B5 -> SDWN MOD25610
A6: 256 | B6: 10 | D6: SDWN IA | E6: =IFERROR(VLOOKUP($M6, Delay!$D$2:$L$200, 2, 0),0) -> 0.14655 | F6: =IFERROR(VLOOKUP($M6, Delay!$D$2:$L$200, 3, 0),0)*2.262 /SQRT(10) -> 0.031559354 | G6: =IFERROR(VLOOKUP($M6, Delay!$D$2:$L$200, 4, 0),0) -> 0.14176 | H6: =IFERROR(VLOOKUP($M6, Delay!$D$2:$L$200, 5, 0),0)*2.262 /SQRT(10) -> 0.02975678 | I6: =IFERROR(VLOOKUP($M6, Delay!$D$2:$L$200, 6, 0),0) -> 0.14582 | J6: =IFERROR(VLOOKUP($M6, Delay!$D$2:$L$200, 7, 0),0)*2.262 /SQRT(10) -> 0.042031451 | K6: =IFERROR(VLOOKUP($M6, Delay!$D$2:$L$200, 8, 0),0) -> 0.1415 | L6: =IFERROR(VLOOKUP($M6, Delay!$D$2:$L$200, 9, 0),0)*2.262 /SQRT(10) -> 0.046659489 | M6: =D6&A6&B6 -> SDWN IA25610
A7: 256 | B7: 20 | C7: \multirow{4}{*}{20} | D7: NO SDWN | E7: =IFERROR(VLOOKUP($M7, Delay!$D$2:$L$200, 2, 0),0) -> 0.22666 | F7: =IFERROR(VLOOKUP($M7, Delay!$D$2:$L$200, 3, 0),0)*2.262 /SQRT(10) -> 0.069785371 | G7: =IFERROR(VLOOKUP($M7, Delay!$D$2:$L$200, 4, 0),0) -> 0.18668 | H7: =IFERROR(VLOOKUP($M7, Delay!$D$2:$L$200, 5, 0),0)*2.262 /SQRT(10) -> 0.064685231 | I7: =IFERROR(VLOOKUP($M7, Delay!$D$2:$L$200, 6, 0),0) -> 0.16038 | J7: =IFERROR(VLOOKUP($M7, Delay!$D$2:$L$200, 7, 0),0)*2.262 /SQRT(10) -> 0.052160202 | K7: =IFERROR(VLOOKUP($M7, Delay!$D$2:$L$200, 8, 0),0) -> 0.18505 | L7: =IFERROR(VLOOKUP($M7, Delay!$D$2:$L$200, 9, 0),0)*2.262 /SQRT(10) -> 0.06342629 | M7: =D7&A7&B7 -> NO SDWN25620
A8: 256 | B8: 20 | D8: SDWN EDCA | E8: =IFERROR(VLOOKUP($M8, Delay!$D$2:$L$200, 2, 0),0) -> 0.16176 | F8: =IFERROR(VLOOKUP($M8, Delay!$D$2:$L$200, 3, 0),0)*2.262 /SQRT(10) -> 0.038962784 | G8: =IFERROR(VLOOKUP($M8, Delay!$D$2:$L$200, 4, 0),0) -> 0.16214 | H8: =IFERROR(VLOOKUP($M8, Delay!$D$2:$L$200, 5, 0),0)*2.262 /SQRT(10) -> 0.053133019 | I8: =IFERROR(VLOOKUP($M8, Delay!$D$2:$L$200, 6, 0),0) -> 0.16458 | J8: =IFERROR(VLOOKUP($M8, Delay!$D$2:$L$200, 7, 0),0)*2.262 /SQRT(10) -> 0.057510699 | K8: =IFERROR(VLOOKUP($M8, Delay!$D$2:$L$200, 8, 0),0) -> 0.19293 | L8: =IFERROR(VLOOKUP($M8, Delay!$D$2:$L$200, 9, 0),0)*2.262 /SQRT(10) -> 0.065865488 | M8: =D8&A8&B8 -> SDWN EDCA25620
A9: 256 | B9: 20 | D9: SDWN MOD | E9: =IFERROR(VLOOKUP($M9, Delay!$D$2:$L$200, 2, 0),0) -> 0.2233 | F9: =IFERROR(VLOOKUP($M9, Delay!$D$2:$L$200, 3, 0),0)*2.262 /SQRT(10) -> 0.072896957 | G9: =IFERROR(VLOOKUP($M9, Delay!$D$2:$L$200, 4, 0),0) -> 0.18988 | H9: =IFERROR(VLOOKUP($M9, Delay!$D$2:$L$200, 5, 0),0)*2.262 /SQRT(10) -> 0.070092953 | I9: =IFERROR(VLOOKUP($M9, Delay!$D$2:$L$200, 6, 0),0) -> 0.16422 | J9: =IFERROR(VLOOKUP($M9, Delay!$D$2:$L$200, 7, 0),0)*2.262 /SQRT(10) -> 0.060028581 | K9: =IFERROR(VLOOKUP($M9, Delay!$D$2:$L$200, 8, 0),0) -> 0.191 | L9: =IFERROR(VLOOKUP($M9, Delay!$D$2:$L$200, 9, 0),0)*2.262 /SQRT(10) -> 0.065929865 | M9: =D9&A9&B9 -> SDWN MOD25620
A10: 256 | B10: 20 | D10: SDWN IA | E10: =IFERROR(VLOOKUP($M10, Delay!$D$2:$L$200, 2, 0),0) -> 0.20264 | F10: =IFERROR(VLOOKUP($M10, Delay!$D$2:$L$200, 3, 0),0)*2.262 /SQRT(10) -> 0.18216729 | G10: =IFERROR(VLOOKUP($M10, Delay!$D$2:$L$200, 4, 0),0) -> 0.16841 | H10: =IFERROR(VLOOKUP($M10, Delay!$D$2:$L$200, 5, 0),0)*2.262 /SQRT(10) -> 0.045243181 | I10: =IFERROR(VLOOKUP($M10, Delay!$D$2:$L$200, 6, 0),0) -> 0.14864 | J10: =IFERROR(VLOOKUP($M10, Delay!$D$2:$L$200, 7, 0),0)*2.262 /SQRT(10) -> 0.039949907 | K10: =IFERROR(VLOOKUP($M10, Delay!$D$2:$L$200, 8, 0),0) -> 0.1708 | L10: =IFERROR(VLOOKUP($M10, Delay!$D$2:$L$200, 9, 0),0)*2.262 /SQRT(10) -> 0.05832615 | M10: =D10&A10&B10 -> SDWN IA25620
A11: 256 | B11: 30 | C11: \multirow{4}{*}{30} | D11: NO SDWN | E11: =IFERROR(VLOOKUP($M11, Delay!$D$2:$L$200, 2, 0),0) -> 0.24792 | F11: =IFERROR(VLOOKUP($M11, Delay!$D$2:$L$200, 3, 0),0)*2.262 /SQRT(10) -> 0.083326137 | G11: =IFERROR(VLOOKUP($M11, Delay!$D$2:$L$200, 4, 0),0) -> 0.1987 | H11: =IFERROR(VLOOKUP($M11, Delay!$D$2:$L$200, 5, 0),0)*2.262 /SQRT(10) -> 0.059463488 | I11: =IFERROR(VLOOKUP($M11, Delay!$D$2:$L$200, 6, 0),0) -> 0.16873 | J11: =IFERROR(VLOOKUP($M11, Delay!$D$2:$L$200, 7, 0),0)*2.262 /SQRT(10) -> 0.056695249 | K11: =IFERROR(VLOOKUP($M11, Delay!$D$2:$L$200, 8, 0),0) -> 0.17811 | L11: =IFERROR(VLOOKUP($M11, Delay!$D$2:$L$200, 9, 0),0)*2.262 /SQRT(10) -> 0.058690956 | M11: =D11&A11&B11 -> NO SDWN25630
A12: 256 | B12: 30 | D12: SDWN EDCA | E12: =IFERROR(VLOOKUP($M12, Delay!$D$2:$L$200, 2, 0),0) -> 0.17869 | F12: =IFERROR(VLOOKUP($M12, Delay!$D$2:$L$200, 3, 0),0)*2.262 /SQRT(10) -> 0.052889815 | G12: =IFERROR(VLOOKUP($M12, Delay!$D$2:$L$200, 4, 0),0) -> 0.1758 | H12: =IFERROR(VLOOKUP($M12, Delay!$D$2:$L$200, 5, 0),0)*2.262 /SQRT(10) -> 0.053125866 | I12: =IFERROR(VLOOKUP($M12, Delay!$D$2:$L$200, 6, 0),0) -> 0.17045 | J12: =IFERROR(VLOOKUP($M12, Delay!$D$2:$L$200, 7, 0),0)*2.262 /SQRT(10) -> 0.06105147 | K12: =IFERROR(VLOOKUP($M12, Delay!$D$2:$L$200, 8, 0),0) -> 0.18127 | L12: =IFERROR(VLOOKUP($M12, Delay!$D$2:$L$200, 9, 0),0)*2.262 /SQRT(10) -> 0.060422 | M12: =D12&A12&B12 -> SDWN EDCA25630
A13: 256 | B13: 30 | D13: SDWN MOD | E13: =IFERROR(VLOOKUP($M13, Delay!$D$2:$L$200, 2, 0),0) -> 0.22969 | F13: =IFERROR(VLOOKUP($M13, Delay!$D$2:$L$200, 3, 0),0)*2.262 /SQRT(10) -> 0.072524998 | G13: =IFERROR(VLOOKUP($M13, Delay!$D$2:$L$200, 4, 0),0) -> 0.20205 | H13: =IFERROR(VLOOKUP($M13, Delay!$D$2:$L$200, 5, 0),0)*2.262 /SQRT(10) -> 0.069849749 | I13: =IFERROR(VLOOKUP($M13, Delay!$D$2:$L$200, 6, 0),0) -> 0.17197 | J13: =IFERROR(VLOOKUP($M13, Delay!$D$2:$L$200, 7, 0),0)*2.262 /SQRT(10) -> 0.064270353 | K13: =IFERROR(VLOOKUP($M13, Delay!$D$2:$L$200, 8, 0),0) -> 0.17702 | L13: =IFERROR(VLOOKUP($M13, Delay!$D$2:$L$200, 9, 0),0)*2.262 /SQRT(10) -> 0.056144463 | M13: =D13&A13&B13 -> SDWN MOD25630
A14: 256 | B14: 30 | D14: SDWN IA | E14: =IFERROR(VLOOKUP($M14, Delay!$D$2:$L$200, 2, 0),0) -> 0.17371 | F14: =IFERROR(VLOOKUP($M14, Delay!$D$2:$L$200, 3, 0),0)*2.262 /SQRT(10) -> 0.045736743 | G14: =IFERROR(VLOOKUP($M14, Delay!$D$2:$L$200, 4, 0),0) -> 0.15284 | H14: =IFERROR(VLOOKUP($M14, Delay!$D$2:$L$200, 5, 0),0)*2.262 /SQRT(10) -> 0.045164497 | I14: =IFERROR(VLOOKUP($M14, Delay!$D$2:$L$200, 6, 0),0) -> 0.17572 | J14: =IFERROR(VLOOKUP($M14, Delay!$D$2:$L$200, 7, 0),0)*2.262 /SQRT(10) -> 0.047846899 | K14: =IFERROR(VLOOKUP($M14, Delay!$D$2:$L$200, 8, 0),0) -> 0.18302 | L14: =IFERROR(VLOOKUP($M14, Delay!$D$2:$L$200, 9, 0),0)*2.262 /SQRT(10) -> 0.065751038 | M14: =D14&A14&B14 -> SDWN IA25630
A15: 256 | B15: 40 | C15: \multirow{4}{*}{40} | D15: NO SDWN | E15: =IFERROR(VLOOKUP($M15, Delay!$D$2:$L$200, 2, 0),0) -> 0.28039 | F15: =IFERROR(VLOOKUP($M15, Delay!$D$2:$L$200, 3, 0),0)*2.262 /SQRT(10) -> 0.088776777 | G15: =IFERROR(VLOOKUP($M15, Delay!$D$2:$L$200, 4, 0),0) -> 0.20848 | H15: =IFERROR(VLOOKUP($M15, Delay!$D$2:$L$200, 5, 0),0)*2.262 /SQRT(10) -> 0.078547884 | I15: =IFERROR(VLOOKUP($M15, Delay!$D$2:$L$200, 6, 0),0) -> 0.19812 | J15: =IFERROR(VLOOKUP($M15, Delay!$D$2:$L$200, 7, 0),0)*2.262 /SQRT(10) -> 0.072160191 | K15: =IFERROR(VLOOKUP($M15, Delay!$D$2:$L$200, 8, 0),0) -> 0.18802 | L15: =IFERROR(VLOOKUP($M15, Delay!$D$2:$L$200, 9, 0),0)*2.262 /SQRT(10) -> 0.060565061 | M15: =D15&A15&B15 -> NO SDWN25640
A16: 256 | B16: 40 | D16: SDWN EDCA | E16: =IFERROR(VLOOKUP($M16, Delay!$D$2:$L$200, 2, 0),0) -> 0.20486 | F16: =IFERROR(VLOOKUP($M16, Delay!$D$2:$L$200, 3, 0),0)*2.262 /SQRT(10) -> 0.056609412 | G16: =IFERROR(VLOOKUP($M16, Delay!$D$2:$L$200, 4, 0),0) -> 0.1648 | H16: =IFERROR(VLOOKUP($M16, Delay!$D$2:$L$200, 5, 0),0)*2.262 /SQRT(10) -> 0.049327585 | I16: =IFERROR(VLOOKUP($M16, Delay!$D$2:$L$200, 6, 0),0) -> 0.1895 | J16: =IFERROR(VLOOKUP($M16, Delay!$D$2:$L$200, 7, 0),0)*2.262 /SQRT(10) -> 0.068612267 | K16: =IFERROR(VLOOKUP($M16, Delay!$D$2:$L$200, 8, 0),0) -> 0.19884 | L16: =IFERROR(VLOOKUP($M16, Delay!$D$2:$L$200, 9, 0),0)*2.262 /SQRT(10) -> 0.063855474 | M16: =D16&A16&B16 -> SDWN EDCA25640
A17: 256 | B17: 40 | D17: SDWN MOD | E17: =IFERROR(VLOOKUP($M17, Delay!$D$2:$L$200, 2, 0),0) -> 0.2603 | F17: =IFERROR(VLOOKUP($M17, Delay!$D$2:$L$200, 3, 0),0)*2.262 /SQRT(10) -> 0.077353321 | G17: =IFERROR(VLOOKUP($M17, Delay!$D$2:$L$200, 4, 0),0) -> 0.1837 | H17: =IFERROR(VLOOKUP($M17, Delay!$D$2:$L$200, 5, 0),0)*2.262 /SQRT(10) -> 0.062110125 | I17: =IFERROR(VLOOKUP($M17, Delay!$D$2:$L$200, 6, 0),0) -> 0.19048 | J17: =IFERROR(VLOOKUP($M17, Delay!$D$2:$L$200, 7, 0),0)*2.262 /SQRT(10) -> 0.072575069 | K17: =IFERROR(VLOOKUP($M17, Delay!$D$2:$L$200, 8, 0),0) -> 0.20553 | L17: =IFERROR(VLOOKUP($M17, Delay!$D$2:$L$200, 9, 0),0)*2.262 /SQRT(10) -> 0.13572239 | M17: =D17&A17&B17 -> SDWN MOD25640
A18: 256 | B18: 40 | D18: SDWN IA | E18: =IFERROR(VLOOKUP($M18, Delay!$D$2:$L$200, 2, 0),0) -> 0.20233 | F18: =IFERROR(VLOOKUP($M18, Delay!$D$2:$L$200, 3, 0),0)*2.262 /SQRT(10) -> 0.062825432 | G18: =IFERROR(VLOOKUP($M18, Delay!$D$2:$L$200, 4, 0),0) -> 0.18739 | H18: =IFERROR(VLOOKUP($M18, Delay!$D$2:$L$200, 5, 0),0)*2.262 /SQRT(10) -> 0.06086549 | I18: =IFERROR(VLOOKUP($M18, Delay!$D$2:$L$200, 6, 0),0) -> 0.15362 | J18: =IFERROR(VLOOKUP($M18, Delay!$D$2:$L$200, 7, 0),0)*2.262 /SQRT(10) -> 0.046158774 | K18: =IFERROR(VLOOKUP($M18, Delay!$D$2:$L$200, 8, 0),0) -> 0.19791 | L18: =IFERROR(VLOOKUP($M18, Delay!$D$2:$L$200, 9, 0),0)*2.262 /SQRT(10) -> 0.073168774 | M18: =D18&A18&B18 -> SDWN IA25640
A19: 256 | B19: 50 | C19: \multirow{4}{*}{50} | D19: NO SDWN | E19: =IFERROR(VLOOKUP($M19, Delay!$D$2:$L$200, 2, 0),0) -> 0.76274 | F19: =IFERROR(VLOOKUP($M19, Delay!$D$2:$L$200, 3, 0),0)*2.262 /SQRT(10) -> 0.29089398 | G19: =IFERROR(VLOOKUP($M19, Delay!$D$2:$L$200, 4, 0),0) -> 0.20378 | H19: =IFERROR(VLOOKUP($M19, Delay!$D$2:$L$200, 5, 0),0)*2.262 /SQRT(10) -> 0.082231716 | I19: =IFERROR(VLOOKUP($M19, Delay!$D$2:$L$200, 6, 0),0) -> 0.20503 | J19: =IFERROR(VLOOKUP($M19, Delay!$D$2:$L$200, 7, 0),0)*2.262 /SQRT(10) -> 0.078233149 | K19: =IFERROR(VLOOKUP($M19, Delay!$D$2:$L$200, 8, 0),0) -> 0.67477 | L19: =IFERROR(VLOOKUP($M19, Delay!$D$2:$L$200, 9, 0),0)*2.262 /SQRT(10) -> 0.25021446 | M19: =D19&A19&B19 -> NO SDWN25650
A20: 256 | B20: 50 | D20: SDWN EDCA | E20: =IFERROR(VLOOKUP($M20, Delay!$D$2:$L$200, 2, 0),0) -> 0.37802 | F20: =IFERROR(VLOOKUP($M20, Delay!$D$2:$L$200, 3, 0),0)*2.262 /SQRT(10) -> 0.10929179 | G20: =IFERROR(VLOOKUP($M20, Delay!$D$2:$L$200, 4, 0),0) -> 0.17694 | H20: =IFERROR(VLOOKUP($M20, Delay!$D$2:$L$200, 5, 0),0)*2.262 /SQRT(10) -> 0.061380511 | I20: =IFERROR(VLOOKUP($M20, Delay!$D$2:$L$200, 6, 0),0) -> 0.19548 | J20: =IFERROR(VLOOKUP($M20, Delay!$D$2:$L$200, 7, 0),0)*2.262 /SQRT(10) -> 0.06689553 | K20: =IFERROR(VLOOKUP($M20, Delay!$D$2:$L$200, 8, 0),0) -> 0.92688 | L20: =IFERROR(VLOOKUP($M20, Delay!$D$2:$L$200, 9, 0),0)*2.262 /SQRT(10) -> 0.38314715 | M20: =D20&A20&B20 -> SDWN EDCA25650
A21: 256 | B21: 50 | D21: SDWN MOD | E21: =IFERROR(VLOOKUP($M21, Delay!$D$2:$L$200, 2, 0),0) -> 0.61098 | F21: =IFERROR(VLOOKUP($M21, Delay!$D$2:$L$200, 3, 0),0)*2.262 /SQRT(10) -> 0.22683107 | G21: =IFERROR(VLOOKUP($M21, Delay!$D$2:$L$200, 4, 0),0) -> 0.19845 | H21: =IFERROR(VLOOKUP($M21, Delay!$D$2:$L$200, 5, 0),0)*2.262 /SQRT(10) -> 0.13165229 | I21: =IFERROR(VLOOKUP($M21, Delay!$D$2:$L$200, 6, 0),0) -> 0.18126 | J21: =IFERROR(VLOOKUP($M21, Delay!$D$2:$L$200, 7, 0),0)*2.262 /SQRT(10) -> 0.060522143 | K21: =IFERROR(VLOOKUP($M21, Delay!$D$2:$L$200, 8, 0),0) -> 0.85395 | L21: =IFERROR(VLOOKUP($M21, Delay!$D$2:$L$200, 9, 0),0)*2.262 /SQRT(10) -> 0.36891969 | M21: =D21&A21&B21 -> SDWN MOD25650
A22: 256 | B22: 50 | D22: SDWN IA | E22: =IFERROR(VLOOKUP($M22, Delay!$D$2:$L$200, 2, 0),0) -> 0.35496 | F22: =IFERROR(VLOOKUP($M22, Delay!$D$2:$L$200, 3, 0),0)*2.262 /SQRT(10) -> 0.10280395 | G22: =IFERROR(VLOOKUP($M22, Delay!$D$2:$L$200, 4, 0),0) -> 0.19547 | H22: =IFERROR(VLOOKUP($M22, Delay!$D$2:$L$200, 5, 0),0)*2.262 /SQRT(10) -> 0.065550752 | I22: =IFERROR(VLOOKUP($M22, Delay!$D$2:$L$200, 6, 0),0) -> 0.19956 | J22: =IFERROR(VLOOKUP($M22, Delay!$D$2:$L$200, 7, 0),0)*2.262 /SQRT(10) -> 0.076430575 | K22: =IFERROR(VLOOKUP($M22, Delay!$D$2:$L$200, 8, 0),0) -> 0.89063 | L22: =IFERROR(VLOOKUP($M22, Delay!$D$2:$L$200, 9, 0),0)*2.262 /SQRT(10) -> 0.33019296 | M22: =D22&A22&B22 -> SDWN IA25650
A23: 256 | B23: 60 | C23: \multirow{4}{*}{60} | D23: NO SDWN | E23: =IFERROR(VLOOKUP($M23, Delay!$D$2:$L$200, 2, 0),0) -> 0.9394 | F23: =IFERROR(VLOOKUP($M23, Delay!$D$2:$L$200, 3, 0),0)*2.262 /SQRT(10) -> 0.24148771 | G23: =IFERROR(VLOOKUP($M23, Delay!$D$2:$L$200, 4, 0),0) -> 0.45998 | H23: =IFERROR(VLOOKUP($M23, Delay!$D$2:$L$200, 5, 0),0)*2.262 /SQRT(10) -> 0.28959928 | I23: =IFERROR(VLOOKUP($M23, Delay!$D$2:$L$200, 6, 0),0) -> 0.39169 | J23: =IFERROR(VLOOKUP($M23, Delay!$D$2:$L$200, 7, 0),0)*2.262 /SQRT(10) -> 0.23746053 | K23: =IFERROR(VLOOKUP($M23, Delay!$D$2:$L$200, 8, 0),0) -> 0.8096 | L23: =IFERROR(VLOOKUP($M23, Delay!$D$2:$L$200, 9, 0),0)*2.262 /SQRT(10) -> 0.21756069 | M23: =D23&A23&B23 -> NO SDWN25660
A24: 256 | B24: 60 | D24: SDWN EDCA | E24: =IFERROR(VLOOKUP($M24, Delay!$D$2:$L$200, 2, 0),0) -> 0.44873 | F24: =IFERROR(VLOOKUP($M24, Delay!$D$2:$L$200, 3, 0),0)*2.262 /SQRT(10) -> 0.093147304 | G24: =IFERROR(VLOOKUP($M24, Delay!$D$2:$L$200, 4, 0),0) -> 0.29175 | H24: =IFERROR(VLOOKUP($M24, Delay!$D$2:$L$200, 5, 0),0)*2.262 /SQRT(10) -> 0.11996417 | I24: =IFERROR(VLOOKUP($M24, Delay!$D$2:$L$200, 6, 0),0) -> 0.46673 | J24: =IFERROR(VLOOKUP($M24, Delay!$D$2:$L$200, 7, 0),0)*2.262 /SQRT(10) -> 0.32941327 | K24: =IFERROR(VLOOKUP($M24, Delay!$D$2:$L$200, 8, 0),0) -> 1.04607 | L24: =IFERROR(VLOOKUP($M24, Delay!$D$2:$L$200, 9, 0),0)*2.262 /SQRT(10) -> 0.30190971 | M24: =D24&A24&B24 -> SDWN EDCA25660
A25: 256 | B25: 60 | D25: SDWN MOD | E25: =IFERROR(VLOOKUP($M25, Delay!$D$2:$L$200, 2, 0),0) -> 0.72113 | F25: =IFERROR(VLOOKUP($M25, Delay!$D$2:$L$200, 3, 0),0)*2.262 /SQRT(10) -> 0.17799705 | G25: =IFERROR(VLOOKUP($M25, Delay!$D$2:$L$200, 4, 0),0) -> 0.35193 | H25: =IFERROR(VLOOKUP($M25, Delay!$D$2:$L$200, 5, 0),0)*2.262 /SQRT(10) -> 0.18415584 | I25: =IFERROR(VLOOKUP($M25, Delay!$D$2:$L$200, 6, 0),0) -> 0.39831 | J25: =IFERROR(VLOOKUP($M25, Delay!$D$2:$L$200, 7, 0),0)*2.262 /SQRT(10) -> 0.27071517 | K25: =IFERROR(VLOOKUP($M25, Delay!$D$2:$L$200, 8, 0),0) -> 0.94088 | L25: =IFERROR(VLOOKUP($M25, Delay!$D$2:$L$200, 9, 0),0)*2.262 /SQRT(10) -> 0.24105138 | M25: =D25&A25&B25 -> SDWN MOD25660
A26: 256 | B26: 60 | D26: SDWN IA | E26: =IFERROR(VLOOKUP($M26, Delay!$D$2:$L$200, 2, 0),0) -> 0.43167 | F26: =IFERROR(VLOOKUP($M26, Delay!$D$2:$L$200, 3, 0),0)*2.262 /SQRT(10) -> 0.097603668 | G26: =IFERROR(VLOOKUP($M26, Delay!$D$2:$L$200, 4, 0),0) -> 0.23752 | H26: =IFERROR(VLOOKUP($M26, Delay!$D$2:$L$200, 5, 0),0)*2.262 /SQRT(10) -> 0.089012829 | I26: =IFERROR(VLOOKUP($M26, Delay!$D$2:$L$200, 6, 0),0) -> 0.54814 | J26: =IFERROR(VLOOKUP($M26, Delay!$D$2:$L$200, 7, 0),0)*2.262 /SQRT(10) -> 0.37548621 | K26: =IFERROR(VLOOKUP($M26, Delay!$D$2:$L$200, 8, 0),0) -> 1.00874 | L26: =IFERROR(VLOOKUP($M26, Delay!$D$2:$L$200, 9, 0),0)*2.262 /SQRT(10) -> 0.25481389 | M26: =D26&A26&B26 -> SDWN IA25660
A27: 256 | B27: 70 | C27: \multirow{4}{*}{70} | D27: NO SDWN | E27: =IFERROR(VLOOKUP($M27, Delay!$D$2:$L$200, 2, 0),0) -> 0.9477 | F27: =IFERROR(VLOOKUP($M27, Delay!$D$2:$L$200, 3, 0),0)*2.262 /SQRT(10) -> 0.26447769 | G27: =IFERROR(VLOOKUP($M27, Delay!$D$2:$L$200, 4, 0),0) -> 0.67734 | H27: =IFERROR(VLOOKUP($M27, Delay!$D$2:$L$200, 5, 0),0)*2.262 /SQRT(10) -> 0.32222444 | I27: =IFERROR(VLOOKUP($M27, Delay!$D$2:$L$200, 6, 0),0) -> 0.65318 | J27: =IFERROR(VLOOKUP($M27, Delay!$D$2:$L$200, 7, 0),0)*2.262 /SQRT(10) -> 0.25897697 | K27: =IFERROR(VLOOKUP($M27, Delay!$D$2:$L$200, 8, 0),0) -> 0.86462 | L27: =IFERROR(VLOOKUP($M27, Delay!$D$2:$L$200, 9, 0),0)*2.262 /SQRT(10) -> 0.23673092 | M27: =D27&A27&B27 -> NO SDWN25670
A28: 256 | B28: 70 | D28: SDWN EDCA | E28: =IFERROR(VLOOKUP($M28, Delay!$D$2:$L$200, 2, 0),0) -> 0.44942 | F28: =IFERROR(VLOOKUP($M28, Delay!$D$2:$L$200, 3, 0),0)*2.262 /SQRT(10) -> 0.095822553 | G28: =IFERROR(VLOOKUP($M28, Delay!$D$2:$L$200, 4, 0),0) -> 0.35627 | H28: =IFERROR(VLOOKUP($M28, Delay!$D$2:$L$200, 5, 0),0)*2.262 /SQRT(10) -> 0.12731038 | I28: =IFERROR(VLOOKUP($M28, Delay!$D$2:$L$200, 6, 0),0) -> 0.77522 | J28: =IFERROR(VLOOKUP($M28, Delay!$D$2:$L$200, 7, 0),0)*2.262 /SQRT(10) -> 0.31969225 | K28: =IFERROR(VLOOKUP($M28, Delay!$D$2:$L$200, 8, 0),0) -> 1.03802 | L28: =IFERROR(VLOOKUP($M28, Delay!$D$2:$L$200, 9, 0),0)*2.262 /SQRT(10) -> 0.3361157 | M28: =D28&A28&B28 -> SDWN EDCA25670
A29: 256 | B29: 70 | D29: SDWN MOD | E29: =IFERROR(VLOOKUP($M29, Delay!$D$2:$L$200, 2, 0),0) -> 0.6939 | F29: =IFERROR(VLOOKUP($M29, Delay!$D$2:$L$200, 3, 0),0)*2.262 /SQRT(10) -> 0.17792551 | G29: =IFERROR(VLOOKUP($M29, Delay!$D$2:$L$200, 4, 0),0) -> 0.46175 | H29: =IFERROR(VLOOKUP($M29, Delay!$D$2:$L$200, 5, 0),0)*2.262 /SQRT(10) -> 0.19647343 | I29: =IFERROR(VLOOKUP($M29, Delay!$D$2:$L$200, 6, 0),0) -> 0.65036 | J29: =IFERROR(VLOOKUP($M29, Delay!$D$2:$L$200, 7, 0),0)*2.262 /SQRT(10) -> 0.26292547 | K29: =IFERROR(VLOOKUP($M29, Delay!$D$2:$L$200, 8, 0),0) -> 0.93509 | L29: =IFERROR(VLOOKUP($M29, Delay!$D$2:$L$200, 9, 0),0)*2.262 /SQRT(10) -> 0.26020015 | M29: =D29&A29&B29 -> SDWN MOD25670
A30: 256 | B30: 70 | D30: SDWN IA | E30: =IFERROR(VLOOKUP($M30, Delay!$D$2:$L$200, 2, 0),0) -> 0.44499 | F30: =IFERROR(VLOOKUP($M30, Delay!$D$2:$L$200, 3, 0),0)*2.262 /SQRT(10) -> 0.089070053 | G30: =IFERROR(VLOOKUP($M30, Delay!$D$2:$L$200, 4, 0),0) -> 0.31429 | H30: =IFERROR(VLOOKUP($M30, Delay!$D$2:$L$200, 5, 0),0)*2.262 /SQRT(10) -> 0.10132327 | I30: =IFERROR(VLOOKUP($M30, Delay!$D$2:$L$200, 6, 0),0) -> 0.66639 | J30: =IFERROR(VLOOKUP($M30, Delay!$D$2:$L$200, 7, 0),0)*2.262 /SQRT(10) -> 0.24784679 | K30: =IFERROR(VLOOKUP($M30, Delay!$D$2:$L$200, 8, 0),0) -> 0.99875 | L30: =IFERROR(VLOOKUP($M30, Delay!$D$2:$L$200, 9, 0),0)*2.262 /SQRT(10) -> 0.25027884 | M30: =D30&A30&B30 -> SDWN IA25670
A31: 256 | B31: 80 | C31: \multirow{4}{*}{80} | D31: NO SDWN | E31: =IFERROR(VLOOKUP($M31, Delay!$D$2:$L$200, 2, 0),0) -> 1.03022 | F31: =IFERROR(VLOOKUP($M31, Delay!$D$2:$L$200, 3, 0),0)*2.262 /SQRT(10) -> 0.27756066 | G31: =IFERROR(VLOOKUP($M31, Delay!$D$2:$L$200, 4, 0),0) -> 0.85127 | H31: =IFERROR(VLOOKUP($M31, Delay!$D$2:$L$200, 5, 0),0)*2.262 /SQRT(10) -> 0.2412302 | I31: =IFERROR(VLOOKUP($M31, Delay!$D$2:$L$200, 6, 0),0) -> 0.84142 | J31: =IFERROR(VLOOKUP($M31, Delay!$D$2:$L$200, 7, 0),0)*2.262 /SQRT(10) -> 0.25521446 | K31: =IFERROR(VLOOKUP($M31, Delay!$D$2:$L$200, 8, 0),0) -> 0.88014 | L31: =IFERROR(VLOOKUP($M31, Delay!$D$2:$L$200, 9, 0),0)*2.262 /SQRT(10) -> 0.24309 | M31: =D31&A31&B31 -> NO SDWN25680
A32: 256 | B32: 80 | D32: SDWN EDCA | E32: =IFERROR(VLOOKUP($M32, Delay!$D$2:$L$200, 2, 0),0) -> 0.47528 | F32: =IFERROR(VLOOKUP($M32, Delay!$D$2:$L$200, 3, 0),0)*2.262 /SQRT(10) -> 0.099155885 | G32: =IFERROR(VLOOKUP($M32, Delay!$D$2:$L$200, 4, 0),0) -> 0.44966 | H32: =IFERROR(VLOOKUP($M32, Delay!$D$2:$L$200, 5, 0),0)*2.262 /SQRT(10) -> 0.10298278 | I32: =IFERROR(VLOOKUP($M32, Delay!$D$2:$L$200, 6, 0),0) -> 0.9818 | J32: =IFERROR(VLOOKUP($M32, Delay!$D$2:$L$200, 7, 0),0)*2.262 /SQRT(10) -> 0.31485677 | K32: =IFERROR(VLOOKUP($M32, Delay!$D$2:$L$200, 8, 0),0) -> 1.00533 | L32: =IFERROR(VLOOKUP($M32, Delay!$D$2:$L$200, 9, 0),0)*2.262 /SQRT(10) -> 0.26166653 | M32: =D32&A32&B32 -> SDWN EDCA25680
A33: 256 | B33: 80 | D33: SDWN MOD | E33: =IFERROR(VLOOKUP($M33, Delay!$D$2:$L$200, 2, 0),0) -> 0.71993 | F33: =IFERROR(VLOOKUP($M33, Delay!$D$2:$L$200, 3, 0),0)*2.262 /SQRT(10) -> 0.16080821 | G33: =IFERROR(VLOOKUP($M33, Delay!$D$2:$L$200, 4, 0),0) -> 0.58794 | H33: =IFERROR(VLOOKUP($M33, Delay!$D$2:$L$200, 5, 0),0)*2.262 /SQRT(10) -> 0.17077244 | I33: =IFERROR(VLOOKUP($M33, Delay!$D$2:$L$200, 6, 0),0) -> 0.81373 | J33: =IFERROR(VLOOKUP($M33, Delay!$D$2:$L$200, 7, 0),0)*2.262 /SQRT(10) -> 0.23618013 | K33: =IFERROR(VLOOKUP($M33, Delay!$D$2:$L$200, 8, 0),0) -> 0.92765 | L33: =IFERROR(VLOOKUP($M33, Delay!$D$2:$L$200, 9, 0),0)*2.262 /SQRT(10) -> 0.26292547 | M33: =D33&A33&B33 -> SDWN MOD25680
A34: 256 | B34: 80 | D34: SDWN IA | E34: =IFERROR(VLOOKUP($M34, Delay!$D$2:$L$200, 2, 0),0) -> 0.48721 | F34: =IFERROR(VLOOKUP($M34, Delay!$D$2:$L$200, 3, 0),0)*2.262 /SQRT(10) -> 0.12103713 | G34: =IFERROR(VLOOKUP($M34, Delay!$D$2:$L$200, 4, 0),0) -> 0.37737 | H34: =IFERROR(VLOOKUP($M34, Delay!$D$2:$L$200, 5, 0),0)*2.262 /SQRT(10) -> 0.069778218 | I34: =IFERROR(VLOOKUP($M34, Delay!$D$2:$L$200, 6, 0),0) -> 0.77154 | J34: =IFERROR(VLOOKUP($M34, Delay!$D$2:$L$200, 7, 0),0)*2.262 /SQRT(10) -> 0.20454925 | K34: =IFERROR(VLOOKUP($M34, Delay!$D$2:$L$200, 8, 0),0) -> 1.0441 | L34: =IFERROR(VLOOKUP($M34, Delay!$D$2:$L$200, 9, 0),0)*2.262 /SQRT(10) -> 0.30213146 | M34: =D34&A34&B34 -> SDWN IA25680
A35: 256 | B35: 90 | C35: \multirow{4}{*}{90} | D35: NO SDWN | E35: =IFERROR(VLOOKUP($M35, Delay!$D$2:$L$200, 2, 0),0) -> 1.3124 | F35: =IFERROR(VLOOKUP($M35, Delay!$D$2:$L$200, 3, 0),0)*2.262 /SQRT(10) -> 0.42070078 | G35: =IFERROR(VLOOKUP($M35, Delay!$D$2:$L$200, 4, 0),0) -> 1.09418 | H35: =IFERROR(VLOOKUP($M35, Delay!$D$2:$L$200, 5, 0),0)*2.262 /SQRT(10) -> 0.34766076 | I35: =IFERROR(VLOOKUP($M35, Delay!$D$2:$L$200, 6, 0),0) -> 0.97032 | J35: =IFERROR(VLOOKUP($M35, Delay!$D$2:$L$200, 7, 0),0)*2.262 /SQRT(10) -> 0.31821156 | K35: =IFERROR(VLOOKUP($M35, Delay!$D$2:$L$200, 8, 0),0) -> 1.16632 | L35: =IFERROR(VLOOKUP($M35, Delay!$D$2:$L$200, 9, 0),0)*2.262 /SQRT(10) -> 0.38860495 | M35: =D35&A35&B35 -> NO SDWN25690
A36: 256 | B36: 90 | D36: SDWN EDCA | E36: =IFERROR(VLOOKUP($M36, Delay!$D$2:$L$200, 2, 0),0) -> 0.56485 | F36: =IFERROR(VLOOKUP($M36, Delay!$D$2:$L$200, 3, 0),0)*2.262 /SQRT(10) -> 0.16612295 | G36: =IFERROR(VLOOKUP($M36, Delay!$D$2:$L$200, 4, 0),0) -> 0.58336 | H36: =IFERROR(VLOOKUP($M36, Delay!$D$2:$L$200, 5, 0),0)*2.262 /SQRT(10) -> 0.20733179 | I36: =IFERROR(VLOOKUP($M36, Delay!$D$2:$L$200, 6, 0),0) -> 1.02392 | J36: =IFERROR(VLOOKUP($M36, Delay!$D$2:$L$200, 7, 0),0)*2.262 /SQRT(10) -> 0.31203846 | K36: =IFERROR(VLOOKUP($M36, Delay!$D$2:$L$200, 8, 0),0) -> 1.19899 | L36: =IFERROR(VLOOKUP($M36, Delay!$D$2:$L$200, 9, 0),0)*2.262 /SQRT(10) -> 0.34396978 | M36: =D36&A36&B36 -> SDWN EDCA25690
A37: 256 | B37: 90 | D37: SDWN MOD | E37: =IFERROR(VLOOKUP($M37, Delay!$D$2:$L$200, 2, 0),0) -> 0.88248 | F37: =IFERROR(VLOOKUP($M37, Delay!$D$2:$L$200, 3, 0),0)*2.262 /SQRT(10) -> 0.27082246 | G37: =IFERROR(VLOOKUP($M37, Delay!$D$2:$L$200, 4, 0),0) -> 0.71027 | H37: =IFERROR(VLOOKUP($M37, Delay!$D$2:$L$200, 5, 0),0)*2.262 /SQRT(10) -> 0.21288258 | I37: =IFERROR(VLOOKUP($M37, Delay!$D$2:$L$200, 6, 0),0) -> 0.86981 | J37: =IFERROR(VLOOKUP($M37, Delay!$D$2:$L$200, 7, 0),0)*2.262 /SQRT(10) -> 0.24095123 | K37: =IFERROR(VLOOKUP($M37, Delay!$D$2:$L$200, 8, 0),0) -> 1.09594 | L37: =IFERROR(VLOOKUP($M37, Delay!$D$2:$L$200, 9, 0),0)*2.262 /SQRT(10) -> 0.30072946 | M37: =D37&A37&B37 -> SDWN MOD25690
A38: 256 | B38: 90 | D38: SDWN IA | E38: =IFERROR(VLOOKUP($M38, Delay!$D$2:$L$200, 2, 0),0) -> 0.57753 | F38: =IFERROR(VLOOKUP($M38, Delay!$D$2:$L$200, 3, 0),0)*2.262 /SQRT(10) -> 0.20154496 | G38: =IFERROR(VLOOKUP($M38, Delay!$D$2:$L$200, 4, 0),0) -> 0.52371 | H38: =IFERROR(VLOOKUP($M38, Delay!$D$2:$L$200, 5, 0),0)*2.262 /SQRT(10) -> 0.15990693 | I38: =IFERROR(VLOOKUP($M38, Delay!$D$2:$L$200, 6, 0),0) -> 1.02392 | J38: =IFERROR(VLOOKUP($M38, Delay!$D$2:$L$200, 7, 0),0)*2.262 /SQRT(10) -> 0.31203846 | K38: =IFERROR(VLOOKUP($M38, Delay!$D$2:$L$200, 8, 0),0) -> 1.15178 | L38: =IFERROR(VLOOKUP($M38, Delay!$D$2:$L$200, 9, 0),0)*2.262 /SQRT(10) -> 0.31956349 | M38: =D38&A38&B38 -> SDWN IA25690
A39: 256 | B39: 100 | C39: \multirow{4}{*}{100} | D39: NO SDWN | E39: =IFERROR(VLOOKUP($M39, Delay!$D$2:$L$200, 2, 0),0) -> 1.60007 | F39: =IFERROR(VLOOKUP($M39, Delay!$D$2:$L$200, 3, 0),0)*2.262 /SQRT(10) -> 0.46234597 | G39: =IFERROR(VLOOKUP($M39, Delay!$D$2:$L$200, 4, 0),0) -> 1.18289 | H39: =IFERROR(VLOOKUP($M39, Delay!$D$2:$L$200, 5, 0),0)*2.262 /SQRT(10) -> 0.37692398 | I39: =IFERROR(VLOOKUP($M39, Delay!$D$2:$L$200, 6, 0),0) -> 1.16571 | J39: =IFERROR(VLOOKUP($M39, Delay!$D$2:$L$200, 7, 0),0)*2.262 /SQRT(10) -> 0.38785387 | K39: =IFERROR(VLOOKUP($M39, Delay!$D$2:$L$200, 8, 0),0) -> 1.38556 | L39: =IFERROR(VLOOKUP($M39, Delay!$D$2:$L$200, 9, 0),0)*2.262 /SQRT(10) -> 0.38295402 | M39: =D39&A39&B39 -> NO SDWN256100
A40: 256 | B40: 100 | D40: SDWN EDCA | E40: =IFERROR(VLOOKUP($M40, Delay!$D$2:$L$200, 2, 0),0) -> 0.64827 | F40: =IFERROR(VLOOKUP($M40, Delay!$D$2:$L$200, 3, 0),0)*2.262 /SQRT(10) -> 0.21680246 | G40: =IFERROR(VLOOKUP($M40, Delay!$D$2:$L$200, 4, 0),0) -> 0.66649 | H40: =IFERROR(VLOOKUP($M40, Delay!$D$2:$L$200, 5, 0),0)*2.262 /SQRT(10) -> 0.23915581 | I40: =IFERROR(VLOOKUP($M40, Delay!$D$2:$L$200, 6, 0),0) -> 1.08346 | J40: =IFERROR(VLOOKUP($M40, Delay!$D$2:$L$200, 7, 0),0)*2.262 /SQRT(10) -> 0.31651629 | K40: =IFERROR(VLOOKUP($M40, Delay!$D$2:$L$200, 8, 0),0) -> 1.38203 | L40: =IFERROR(VLOOKUP($M40, Delay!$D$2:$L$200, 9, 0),0)*2.262 /SQRT(10) -> 0.34977807 | M40: =D40&A40&B40 -> SDWN EDCA256100
...

Sheet Resumen Lost Packets
A1: Packet Size | B1: Total Devices | D1: Netwoks Config. | E1: HIGH | G1: MEDIUM | I1: LOW | K1: NRT
E2: Mean | F2: +e(95%) | G2: Mean | H2: +e(95%) | I2: Mean | J2: +e(95%) | K2: Mean | L2: +e(95%) | M2: CLAVES
A3: 256 | B3: 10 | C3: \multirow{4}{*}{10} | D3: NO SDWN | E3: =IFERROR(VLOOKUP($M3, LostPackets!$D$2:$L$200, 2, 0),0) -> 0.01111 | F3: =IFERROR(VLOOKUP($M3, LostPackets!$D$2:$L$200, 3, 0),0)*2.262 /SQRT(10) -> 0.029735321 | G3: =IFERROR(VLOOKUP($M3, LostPackets!$D$2:$L$200, 4, 0),0) -> 0.00556 | H3: =IFERROR(VLOOKUP($M3, LostPackets!$D$2:$L$200, 5, 0),0)*2.262 /SQRT(10) -> 0.021401992 | I3: =IFERROR(VLOOKUP($M3, LostPackets!$D$2:$L$200, 6, 0),0) -> 0.025 | J3: =IFERROR(VLOOKUP($M3, LostPackets!$D$2:$L$200, 7, 0),0)*2.262 /SQRT(10) -> 0.042567932 | K3: =IFERROR(VLOOKUP($M3, LostPackets!$D$2:$L$200, 8, 0),0) -> 0.025 | L3: =IFERROR(VLOOKUP($M3, LostPackets!$D$2:$L$200, 9, 0),0)*2.262 /SQRT(10) -> 0.042567932 | M3: =D3&A3&B3 -> NO SDWN25610
A4: 256 | B4: 10 | D4: SDWN EDCA | E4: =IFERROR(VLOOKUP($M4, LostPackets!$D$2:$L$200, 2, 0),0) -> 0.02778 | F4: =IFERROR(VLOOKUP($M4, LostPackets!$D$2:$L$200, 3, 0),0)*2.262 /SQRT(10) -> 0.044427731 | G4: =IFERROR(VLOOKUP($M4, LostPackets!$D$2:$L$200, 4, 0),0) -> 0 | H4: =IFERROR(VLOOKUP($M4, LostPackets!$D$2:$L$200, 5, 0),0)*2.262 /SQRT(10) -> 0 | I4: =IFERROR(VLOOKUP($M4, LostPackets!$D$2:$L$200, 6, 0),0) -> 0.01667 | J4: =IFERROR(VLOOKUP($M4, LostPackets!$D$2:$L$200, 7, 0),0)*2.262 /SQRT(10) -> 0.03576536 | K4: =IFERROR(VLOOKUP($M4, LostPackets!$D$2:$L$200, 8, 0),0) -> 0 | L4: =IFERROR(VLOOKUP($M4, LostPackets!$D$2:$L$200, 9, 0),0)*2.262 /SQRT(10) -> 0 | M4: =D4&A4&B4 -> SDWN EDCA25610
A5: 256 | B5: 10 | D5: SDWN MOD | E5: =IFERROR(VLOOKUP($M5, LostPackets!$D$2:$L$200, 2, 0),0) -> 0.02778 | F5: =IFERROR(VLOOKUP($M5, LostPackets!$D$2:$L$200, 3, 0),0)*2.262 /SQRT(10) -> 0.044427731 | G5: =IFERROR(VLOOKUP($M5, LostPackets!$D$2:$L$200, 4, 0),0) -> 0 | H5: =IFERROR(VLOOKUP($M5, LostPackets!$D$2:$L$200, 5, 0),0)*2.262 /SQRT(10) -> 0 | I5: =IFERROR(VLOOKUP($M5, LostPackets!$D$2:$L$200, 6, 0),0) -> 0.01667 | J5: =IFERROR(VLOOKUP($M5, LostPackets!$D$2:$L$200, 7, 0),0)*2.262 /SQRT(10) -> 0.03576536 | K5: =IFERROR(VLOOKUP($M5, LostPackets!$D$2:$L$200, 8, 0),0) -> 0 | L5: =IFERROR(VLOOKUP($M5, LostPackets!$D$2:$L$200, 9, 0),0)*2.262 /SQRT(10) -> 0 | M5: =D5&A5&B5 -> SDWN MOD25610
A6: 256 | B6: 10 | D6: SDWN IA | E6: =IFERROR(VLOOKUP($M6, LostPackets!$D$2:$L$200, 2, 0),0) -> 0.00556 | F6: =IFERROR(VLOOKUP($M6, LostPackets!$D$2:$L$200, 3, 0),0)*2.262 /SQRT(10) -> 0.021401992 | G6: =IFERROR(VLOOKUP($M6, LostPackets!$D$2:$L$200, 4, 0),0) -> 0.01111 | H6: =IFERROR(VLOOKUP($M6, LostPackets!$D$2:$L$200, 5, 0),0)*2.262 /SQRT(10) -> 0.029735321 | I6: =IFERROR(VLOOKUP($M6, LostPackets!$D$2:$L$200, 6, 0),0) -> 0.00833 | J6: =IFERROR(VLOOKUP($M6, LostPackets!$D$2:$L$200, 7, 0),0)*2.262 /SQRT(10) -> 0.025979958 | K6: =IFERROR(VLOOKUP($M6, LostPackets!$D$2:$L$200, 8, 0),0) -> 0 | L6: =IFERROR(VLOOKUP($M6, LostPackets!$D$2:$L$200, 9, 0),0)*2.262 /SQRT(10) -> 0 | M6: =D6&A6&B6 -> SDWN IA25610
A7: 256 | B7: 20 | C7: \multirow{4}{*}{20} | D7: NO SDWN | E7: =IFERROR(VLOOKUP($M7, LostPackets!$D$2:$L$200, 2, 0),0) -> 0.03333 | F7: =IFERROR(VLOOKUP($M7, LostPackets!$D$2:$L$200, 3, 0),0)*2.262 /SQRT(10) -> 0.047689531 | G7: =IFERROR(VLOOKUP($M7, LostPackets!$D$2:$L$200, 4, 0),0) -> 0.02333 | H7: =IFERROR(VLOOKUP($M7, LostPackets!$D$2:$L$200, 5, 0),0)*2.262 /SQRT(10) -> 0.041366216 | I7: =IFERROR(VLOOKUP($M7, LostPackets!$D$2:$L$200, 6, 0),0) -> 0.01 | J7: =IFERROR(VLOOKUP($M7, LostPackets!$D$2:$L$200, 7, 0),0)*2.262 /SQRT(10) -> 0.028311859 | K7: =IFERROR(VLOOKUP($M7, LostPackets!$D$2:$L$200, 8, 0),0) -> 0.00667 | L7: =IFERROR(VLOOKUP($M7, LostPackets!$D$2:$L$200, 9, 0),0)*2.262 /SQRT(10) -> 0.023361933 | M7: =D7&A7&B7 -> NO SDWN25620
A8: 256 | B8: 20 | D8: SDWN EDCA | E8: =IFERROR(VLOOKUP($M8, LostPackets!$D$2:$L$200, 2, 0),0) -> 0.03 | F8: =IFERROR(VLOOKUP($M8, LostPackets!$D$2:$L$200, 3, 0),0)*2.262 /SQRT(10) -> 0.04580112 | G8: =IFERROR(VLOOKUP($M8, LostPackets!$D$2:$L$200, 4, 0),0) -> 0.03 | H8: =IFERROR(VLOOKUP($M8, LostPackets!$D$2:$L$200, 5, 0),0)*2.262 /SQRT(10) -> 0.04580112 | I8: =IFERROR(VLOOKUP($M8, LostPackets!$D$2:$L$200, 6, 0),0) -> 0.01 | J8: =IFERROR(VLOOKUP($M8, LostPackets!$D$2:$L$200, 7, 0),0)*2.262 /SQRT(10) -> 0.028311859 | K8: =IFERROR(VLOOKUP($M8, LostPackets!$D$2:$L$200, 8, 0),0) -> 0.00333 | L8: =IFERROR(VLOOKUP($M8, LostPackets!$D$2:$L$200, 9, 0),0)*2.262 /SQRT(10) -> 0.016688117 | M8: =D8&A8&B8 -> SDWN EDCA25620
A9: 256 | B9: 20 | D9: SDWN MOD | E9: =IFERROR(VLOOKUP($M9, LostPackets!$D$2:$L$200, 2, 0),0) -> 0.03 | F9: =IFERROR(VLOOKUP($M9, LostPackets!$D$2:$L$200, 3, 0),0)*2.262 /SQRT(10) -> 0.04580112 | G9: =IFERROR(VLOOKUP($M9, LostPackets!$D$2:$L$200, 4, 0),0) -> 0.03 | H9: =IFERROR(VLOOKUP($M9, LostPackets!$D$2:$L$200, 5, 0),0)*2.262 /SQRT(10) -> 0.04580112 | I9: =IFERROR(VLOOKUP($M9, LostPackets!$D$2:$L$200, 6, 0),0) -> 0.01 | J9: =IFERROR(VLOOKUP($M9, LostPackets!$D$2:$L$200, 7, 0),0)*2.262 /SQRT(10) -> 0.028311859 | K9: =IFERROR(VLOOKUP($M9, LostPackets!$D$2:$L$200, 8, 0),0) -> 0 | L9: =IFERROR(VLOOKUP($M9, LostPackets!$D$2:$L$200, 9, 0),0)*2.262 /SQRT(10) -> 0 | M9: =D9&A9&B9 -> SDWN MOD25620
A10: 256 | B10: 20 | D10: SDWN IA | E10: =IFERROR(VLOOKUP($M10, LostPackets!$D$2:$L$200, 2, 0),0) -> 0.01667 | F10: =IFERROR(VLOOKUP($M10, LostPackets!$D$2:$L$200, 3, 0),0)*2.262 /SQRT(10) -> 0.03576536 | G10: =IFERROR(VLOOKUP($M10, LostPackets!$D$2:$L$200, 4, 0),0) -> 0.03667 | H10: =IFERROR(VLOOKUP($M10, LostPackets!$D$2:$L$200, 5, 0),0)*2.262 /SQRT(10) -> 0.04938481 | I10: =IFERROR(VLOOKUP($M10, LostPackets!$D$2:$L$200, 6, 0),0) -> 0.01667 | J10: =IFERROR(VLOOKUP($M10, LostPackets!$D$2:$L$200, 7, 0),0)*2.262 /SQRT(10) -> 0.03576536 | K10: =IFERROR(VLOOKUP($M10, LostPackets!$D$2:$L$200, 8, 0),0) -> 0 | L10: =IFERROR(VLOOKUP($M10, LostPackets!$D$2:$L$200, 9, 0),0)*2.262 /SQRT(10) -> 0 | M10: =D10&A10&B10 -> SDWN IA25620
A11: 256 | B11: 30 | C11: \multirow{4}{*}{30} | D11: NO SDWN | E11: =IFERROR(VLOOKUP($M11, LostPackets!$D$2:$L$200, 2, 0),0) -> 0.07083 | F11: =IFERROR(VLOOKUP($M11, LostPackets!$D$2:$L$200, 3, 0),0)*2.262 /SQRT(10) -> 0.061874073 | G11: =IFERROR(VLOOKUP($M11, LostPackets!$D$2:$L$200, 4, 0),0) -> 0.025 | H11: =IFERROR(VLOOKUP($M11, LostPackets!$D$2:$L$200, 5, 0),0)*2.262 /SQRT(10) -> 0.042567932 | I11: =IFERROR(VLOOKUP($M11, LostPackets!$D$2:$L$200, 6, 0),0) -> 0.0119 | J11: =IFERROR(VLOOKUP($M11, LostPackets!$D$2:$L$200, 7, 0),0)*2.262 /SQRT(10) -> 0.030700985 | K11: =IFERROR(VLOOKUP($M11, LostPackets!$D$2:$L$200, 8, 0),0) -> 0.01429 | L11: =IFERROR(VLOOKUP($M11, LostPackets!$D$2:$L$200, 9, 0),0)*2.262 /SQRT(10) -> 0.033376234 | M11: =D11&A11&B11 -> NO SDWN25630
A12: 256 | B12: 30 | D12: SDWN EDCA | E12: =IFERROR(VLOOKUP($M12, LostPackets!$D$2:$L$200, 2, 0),0) -> 0.05485 | F12: =IFERROR(VLOOKUP($M12, LostPackets!$D$2:$L$200, 3, 0),0)*2.262 /SQRT(10) -> 0.0591416 | G12: =IFERROR(VLOOKUP($M12, LostPackets!$D$2:$L$200, 4, 0),0) -> 0.04375 | H12: =IFERROR(VLOOKUP($M12, LostPackets!$D$2:$L$200, 5, 0),0)*2.262 /SQRT(10) -> 0.055736738 | I12: =IFERROR(VLOOKUP($M12, LostPackets!$D$2:$L$200, 6, 0),0) -> 0.0119 | J12: =IFERROR(VLOOKUP($M12, LostPackets!$D$2:$L$200, 7, 0),0)*2.262 /SQRT(10) -> 0.030700985 | K12: =IFERROR(VLOOKUP($M12, LostPackets!$D$2:$L$200, 8, 0),0) -> 0.01449 | L12: =IFERROR(VLOOKUP($M12, LostPackets!$D$2:$L$200, 9, 0),0)*2.262 /SQRT(10) -> 0.033590826 | M12: =D12&A12&B12 -> SDWN EDCA25630
A13: 256 | B13: 30 | D13: SDWN MOD | E13: =IFERROR(VLOOKUP($M13, LostPackets!$D$2:$L$200, 2, 0),0) -> 0.05417 | F13: =IFERROR(VLOOKUP($M13, LostPackets!$D$2:$L$200, 3, 0),0)*2.262 /SQRT(10) -> 0.055836881 | G13: =IFERROR(VLOOKUP($M13, LostPackets!$D$2:$L$200, 4, 0),0) -> 0.03333 | H13: =IFERROR(VLOOKUP($M13, LostPackets!$D$2:$L$200, 5, 0),0)*2.262 /SQRT(10) -> 0.047689531 | I13: =IFERROR(VLOOKUP($M13, LostPackets!$D$2:$L$200, 6, 0),0) -> 0.00952 | J13: =IFERROR(VLOOKUP($M13, LostPackets!$D$2:$L$200, 7, 0),0)*2.262 /SQRT(10) -> 0.027675236 | K13: =IFERROR(VLOOKUP($M13, LostPackets!$D$2:$L$200, 8, 0),0) -> 0.00714 | L13: =IFERROR(VLOOKUP($M13, LostPackets!$D$2:$L$200, 9, 0),0)*2.262 /SQRT(10) -> 0.024148771 | M13: =D13&A13&B13 -> SDWN MOD25630
A14: 256 | B14: 30 | D14: SDWN IA | E14: =IFERROR(VLOOKUP($M14, LostPackets!$D$2:$L$200, 2, 0),0) -> 0.05417 | F14: =IFERROR(VLOOKUP($M14, LostPackets!$D$2:$L$200, 3, 0),0)*2.262 /SQRT(10) -> 0.055836881 | G14: =IFERROR(VLOOKUP($M14, LostPackets!$D$2:$L$200, 4, 0),0) -> 0.01875 | H14: =IFERROR(VLOOKUP($M14, LostPackets!$D$2:$L$200, 5, 0),0)*2.262 /SQRT(10) -> 0.042124441 | I14: =IFERROR(VLOOKUP($M14, LostPackets!$D$2:$L$200, 6, 0),0) -> 0.02619 | J14: =IFERROR(VLOOKUP($M14, LostPackets!$D$2:$L$200, 7, 0),0)*2.262 /SQRT(10) -> 0.047839746 | K14: =IFERROR(VLOOKUP($M14, LostPackets!$D$2:$L$200, 8, 0),0) -> 0.0119 | L14: =IFERROR(VLOOKUP($M14, LostPackets!$D$2:$L$200, 9, 0),0)*2.262 /SQRT(10) -> 0.030700985 | M14: =D14&A14&B14 -> SDWN IA25630
A15: 256 | B15: 40 | C15: \multirow{4}{*}{40} | D15: NO SDWN | E15: =IFERROR(VLOOKUP($M15, LostPackets!$D$2:$L$200, 2, 0),0) -> 0.10333 | F15: =IFERROR(VLOOKUP($M15, LostPackets!$D$2:$L$200, 3, 0),0)*2.262 /SQRT(10) -> 0.08221741 | G15: =IFERROR(VLOOKUP($M15, LostPackets!$D$2:$L$200, 4, 0),0) -> 0.055 | H15: =IFERROR(VLOOKUP($M15, LostPackets!$D$2:$L$200, 5, 0),0)*2.262 /SQRT(10) -> 0.071638017 | I15: =IFERROR(VLOOKUP($M15, LostPackets!$D$2:$L$200, 6, 0),0) -> 0.035 | J15: =IFERROR(VLOOKUP($M15, LostPackets!$D$2:$L$200, 7, 0),0)*2.262 /SQRT(10) -> 0.051401976 | K15: =IFERROR(VLOOKUP($M15, LostPackets!$D$2:$L$200, 8, 0),0) -> 0.01667 | L15: =IFERROR(VLOOKUP($M15, LostPackets!$D$2:$L$200, 9, 0),0)*2.262 /SQRT(10) -> 0.039542182 | M15: =D15&A15&B15 -> NO SDWN25640
A16: 256 | B16: 40 | D16: SDWN EDCA | E16: =IFERROR(VLOOKUP($M16, LostPackets!$D$2:$L$200, 2, 0),0) -> 0.08673 | F16: =IFERROR(VLOOKUP($M16, LostPackets!$D$2:$L$200, 3, 0),0)*2.262 /SQRT(10) -> 0.070693811 | G16: =IFERROR(VLOOKUP($M16, LostPackets!$D$2:$L$200, 4, 0),0) -> 0.03741 | H16: =IFERROR(VLOOKUP($M16, LostPackets!$D$2:$L$200, 5, 0),0)*2.262 /SQRT(10) -> 0.049742463 | I16: =IFERROR(VLOOKUP($M16, LostPackets!$D$2:$L$200, 6, 0),0) -> 0.02234 | J16: =IFERROR(VLOOKUP($M16, LostPackets!$D$2:$L$200, 7, 0),0)*2.262 /SQRT(10) -> 0.040615143 | K16: =IFERROR(VLOOKUP($M16, LostPackets!$D$2:$L$200, 8, 0),0) -> 0.01531 | L16: =IFERROR(VLOOKUP($M16, LostPackets!$D$2:$L$200, 9, 0),0)*2.262 /SQRT(10) -> 0.034427736 | M16: =D16&A16&B16 -> SDWN EDCA25640
A17: 256 | B17: 40 | D17: SDWN MOD | E17: =IFERROR(VLOOKUP($M17, LostPackets!$D$2:$L$200, 2, 0),0) -> 0.08167 | F17: =IFERROR(VLOOKUP($M17, LostPackets!$D$2:$L$200, 3, 0),0)*2.262 /SQRT(10) -> 0.059599396 | G17: =IFERROR(VLOOKUP($M17, LostPackets!$D$2:$L$200, 4, 0),0) -> 0.01347 | H17: =IFERROR(VLOOKUP($M17, LostPackets!$D$2:$L$200, 5, 0),0)*2.262 /SQRT(10) -> 0.032489253 | I17: =IFERROR(VLOOKUP($M17, LostPackets!$D$2:$L$200, 6, 0),0) -> 0.01852 | J17: =IFERROR(VLOOKUP($M17, LostPackets!$D$2:$L$200, 7, 0),0)*2.262 /SQRT(10) -> 0.037467791 | K17: =IFERROR(VLOOKUP($M17, LostPackets!$D$2:$L$200, 8, 0),0) -> 0.00168 | L17: =IFERROR(VLOOKUP($M17, LostPackets!$D$2:$L$200, 9, 0),0)*2.262 /SQRT(10) -> 0.011924171 | M17: =D17&A17&B17 -> SDWN MOD25640
A18: 256 | B18: 40 | D18: SDWN IA | E18: =IFERROR(VLOOKUP($M18, LostPackets!$D$2:$L$200, 2, 0),0) -> 0.09167 | F18: =IFERROR(VLOOKUP($M18, LostPackets!$D$2:$L$200, 3, 0),0)*2.262 /SQRT(10) -> 0.0797496 | G18: =IFERROR(VLOOKUP($M18, LostPackets!$D$2:$L$200, 4, 0),0) -> 0.065 | H18: =IFERROR(VLOOKUP($M18, LostPackets!$D$2:$L$200, 5, 0),0)*2.262 /SQRT(10) -> 0.071323282 | I18: =IFERROR(VLOOKUP($M18, LostPackets!$D$2:$L$200, 6, 0),0) -> 0.02667 | J18: =IFERROR(VLOOKUP($M18, LostPackets!$D$2:$L$200, 7, 0),0)*2.262 /SQRT(10) -> 0.04370527 | K18: =IFERROR(VLOOKUP($M18, LostPackets!$D$2:$L$200, 8, 0),0) -> 0.02167 | L18: =IFERROR(VLOOKUP($M18, LostPackets!$D$2:$L$200, 9, 0),0)*2.262 /SQRT(10) -> 0.043490678 | M18: =D18&A18&B18 -> SDWN IA25640
A19: 256 | B19: 50 | C19: \multirow{4}{*}{50} | D19: NO SDWN | E19: =IFERROR(VLOOKUP($M19, LostPackets!$D$2:$L$200, 2, 0),0) -> 0.10724 | F19: =IFERROR(VLOOKUP($M19, LostPackets!$D$2:$L$200, 3, 0),0)*2.262 /SQRT(10) -> 0.079663764 | G19: =IFERROR(VLOOKUP($M19, LostPackets!$D$2:$L$200, 4, 0),0) -> 0.05469 | H19: =IFERROR(VLOOKUP($M19, LostPackets!$D$2:$L$200, 5, 0),0)*2.262 /SQRT(10) -> 0.074670919 | I19: =IFERROR(VLOOKUP($M19, LostPackets!$D$2:$L$200, 6, 0),0) -> 0.04722 | J19: =IFERROR(VLOOKUP($M19, LostPackets!$D$2:$L$200, 7, 0),0)*2.262 /SQRT(10) -> 0.06379825 | K19: =IFERROR(VLOOKUP($M19, LostPackets!$D$2:$L$200, 8, 0),0) -> 0.02778 | L19: =IFERROR(VLOOKUP($M19, LostPackets!$D$2:$L$200, 9, 0),0)*2.262 /SQRT(10) -> 0.049477799 | M19: =D19&A19&B19 -> NO SDWN25650
A20: 256 | B20: 50 | D20: SDWN EDCA | E20: =IFERROR(VLOOKUP($M20, LostPackets!$D$2:$L$200, 2, 0),0) -> 0.11795 | F20: =IFERROR(VLOOKUP($M20, LostPackets!$D$2:$L$200, 3, 0),0)*2.262 /SQRT(10) -> 0.088040011 | G20: =IFERROR(VLOOKUP($M20, LostPackets!$D$2:$L$200, 4, 0),0) -> 0.05469 | H20: =IFERROR(VLOOKUP($M20, LostPackets!$D$2:$L$200, 5, 0),0)*2.262 /SQRT(10) -> 0.070071494 | I20: =IFERROR(VLOOKUP($M20, LostPackets!$D$2:$L$200, 6, 0),0) -> 0.03361 | J20: =IFERROR(VLOOKUP($M20, LostPackets!$D$2:$L$200, 7, 0),0)*2.262 /SQRT(10) -> 0.05027179 | K20: =IFERROR(VLOOKUP($M20, LostPackets!$D$2:$L$200, 8, 0),0) -> 0.03056 | L20: =IFERROR(VLOOKUP($M20, LostPackets!$D$2:$L$200, 9, 0),0)*2.262 /SQRT(10) -> 0.048626584 | M20: =D20&A20&B20 -> SDWN EDCA25650
A21: 256 | B21: 50 | D21: SDWN MOD | E21: =IFERROR(VLOOKUP($M21, LostPackets!$D$2:$L$200, 2, 0),0) -> 0.08656 | F21: =IFERROR(VLOOKUP($M21, LostPackets!$D$2:$L$200, 3, 0),0)*2.262 /SQRT(10) -> 0.061387664 | G21: =IFERROR(VLOOKUP($M21, LostPackets!$D$2:$L$200, 4, 0),0) -> 0.02308 | H21: =IFERROR(VLOOKUP($M21, LostPackets!$D$2:$L$200, 5, 0),0)*2.262 /SQRT(10) -> 0.041173083 | I21: =IFERROR(VLOOKUP($M21, LostPackets!$D$2:$L$200, 6, 0),0) -> 0.01389 | J21: =IFERROR(VLOOKUP($M21, LostPackets!$D$2:$L$200, 7, 0),0)*2.262 /SQRT(10) -> 0.03294705 | K21: =IFERROR(VLOOKUP($M21, LostPackets!$D$2:$L$200, 8, 0),0) -> 0.00139 | L21: =IFERROR(VLOOKUP($M21, LostPackets!$D$2:$L$200, 9, 0),0)*2.262 /SQRT(10) -> 0.010836904 | M21: =D21&A21&B21 -> SDWN MOD25650
A22: 256 | B22: 50 | D22: SDWN IA | E22: =IFERROR(VLOOKUP($M22, LostPackets!$D$2:$L$200, 2, 0),0) -> 0.10128 | F22: =IFERROR(VLOOKUP($M22, LostPackets!$D$2:$L$200, 3, 0),0)*2.262 /SQRT(10) -> 0.086852601 | G22: =IFERROR(VLOOKUP($M22, LostPackets!$D$2:$L$200, 4, 0),0) -> 0.07051 | H22: =IFERROR(VLOOKUP($M22, LostPackets!$D$2:$L$200, 5, 0),0)*2.262 /SQRT(10) -> 0.076645167 | I22: =IFERROR(VLOOKUP($M22, LostPackets!$D$2:$L$200, 6, 0),0) -> 0.03472 | J22: =IFERROR(VLOOKUP($M22, LostPackets!$D$2:$L$200, 7, 0),0)*2.262 /SQRT(10) -> 0.055271788 | K22: =IFERROR(VLOOKUP($M22, LostPackets!$D$2:$L$200, 8, 0),0) -> 0.01667 | L22: =IFERROR(VLOOKUP($M22, LostPackets!$D$2:$L$200, 9, 0),0)*2.262 /SQRT(10) -> 0.03576536 | M22: =D22&A22&B22 -> SDWN IA25650
A23: 256 | B23: 60 | C23: \multirow{4}{*}{60} | D23: NO SDWN | E23: =IFERROR(VLOOKUP($M23, LostPackets!$D$2:$L$200, 2, 0),0) -> 0.13087 | F23: =IFERROR(VLOOKUP($M23, LostPackets!$D$2:$L$200, 3, 0),0)*2.262 /SQRT(10) -> 0.096251738 | G23: =IFERROR(VLOOKUP($M23, LostPackets!$D$2:$L$200, 4, 0),0) -> 0.07942 | H23: =IFERROR(VLOOKUP($M23, LostPackets!$D$2:$L$200, 5, 0),0)*2.262 /SQRT(10) -> 0.07884116 | I23: =IFERROR(VLOOKUP($M23, LostPackets!$D$2:$L$200, 6, 0),0) -> 0.04222 | J23: =IFERROR(VLOOKUP($M23, LostPackets!$D$2:$L$200, 7, 0),0)*2.262 /SQRT(10) -> 0.067703827 | K23: =IFERROR(VLOOKUP($M23, LostPackets!$D$2:$L$200, 8, 0),0) -> 0.03579 | L23: =IFERROR(VLOOKUP($M23, LostPackets!$D$2:$L$200, 9, 0),0)*2.262 /SQRT(10) -> 0.052710988 | M23: =D23&A23&B23 -> NO SDWN25660
A24: 256 | B24: 60 | D24: SDWN EDCA | E24: =IFERROR(VLOOKUP($M24, LostPackets!$D$2:$L$200, 2, 0),0) -> 0.14414 | F24: =IFERROR(VLOOKUP($M24, LostPackets!$D$2:$L$200, 3, 0),0)*2.262 /SQRT(10) -> 0.10055789 | G24: =IFERROR(VLOOKUP($M24, LostPackets!$D$2:$L$200, 4, 0),0) -> 0.09333 | H24: =IFERROR(VLOOKUP($M24, LostPackets!$D$2:$L$200, 5, 0),0)*2.262 /SQRT(10) -> 0.086494947 | I24: =IFERROR(VLOOKUP($M24, LostPackets!$D$2:$L$200, 6, 0),0) -> 0.04362 | J24: =IFERROR(VLOOKUP($M24, LostPackets!$D$2:$L$200, 7, 0),0)*2.262 /SQRT(10) -> 0.060829725 | K24: =IFERROR(VLOOKUP($M24, LostPackets!$D$2:$L$200, 8, 0),0) -> 0.02349 | L24: =IFERROR(VLOOKUP($M24, LostPackets!$D$2:$L$200, 9, 0),0)*2.262 /SQRT(10) -> 0.043719576 | M24: =D24&A24&B24 -> SDWN EDCA25660
A25: 256 | B25: 60 | D25: SDWN MOD | E25: =IFERROR(VLOOKUP($M25, LostPackets!$D$2:$L$200, 2, 0),0) -> 0.09732 | F25: =IFERROR(VLOOKUP($M25, LostPackets!$D$2:$L$200, 3, 0),0)*2.262 /SQRT(10) -> 0.064935588 | G25: =IFERROR(VLOOKUP($M25, LostPackets!$D$2:$L$200, 4, 0),0) -> 0.03915 | H25: =IFERROR(VLOOKUP($M25, LostPackets!$D$2:$L$200, 5, 0),0)*2.262 /SQRT(10) -> 0.052396253 | I25: =IFERROR(VLOOKUP($M25, LostPackets!$D$2:$L$200, 6, 0),0) -> 0.00444 | J25: =IFERROR(VLOOKUP($M25, LostPackets!$D$2:$L$200, 7, 0),0)*2.262 /SQRT(10) -> 0.019205999 | K25: =IFERROR(VLOOKUP($M25, LostPackets!$D$2:$L$200, 8, 0),0) -> 0 | L25: =IFERROR(VLOOKUP($M25, LostPackets!$D$2:$L$200, 9, 0),0)*2.262 /SQRT(10) -> 0 | M25: =D25&A25&B25 -> SDWN MOD25660
A26: 256 | B26: 60 | D26: SDWN IA | E26: =IFERROR(VLOOKUP($M26, LostPackets!$D$2:$L$200, 2, 0),0) -> 0.12556 | F26: =IFERROR(VLOOKUP($M26, LostPackets!$D$2:$L$200, 3, 0),0)*2.262 /SQRT(10) -> 0.088075776 | G26: =IFERROR(VLOOKUP($M26, LostPackets!$D$2:$L$200, 4, 0),0) -> 0.05778 | H26: =IFERROR(VLOOKUP($M26, LostPackets!$D$2:$L$200, 5, 0),0)*2.262 /SQRT(10) -> 0.063061483 | I26: =IFERROR(VLOOKUP($M26, LostPackets!$D$2:$L$200, 6, 0),0) -> 0.03333 | J26: =IFERROR(VLOOKUP($M26, LostPackets!$D$2:$L$200, 7, 0),0)*2.262 /SQRT(10) -> 0.053318999 | K26: =IFERROR(VLOOKUP($M26, LostPackets!$D$2:$L$200, 8, 0),0) -> 0.02889 | L26: =IFERROR(VLOOKUP($M26, LostPackets!$D$2:$L$200, 9, 0),0)*2.262 /SQRT(10) -> 0.049148758 | M26: =D26&A26&B26 -> SDWN IA25660
A27: 256 | B27: 70 | C27: \multirow{4}{*}{70} | D27: NO SDWN | E27: =IFERROR(VLOOKUP($M27, LostPackets!$D$2:$L$200, 2, 0),0) -> 0.147 | F27: =IFERROR(VLOOKUP($M27, LostPackets!$D$2:$L$200, 3, 0),0)*2.262 /SQRT(10) -> 0.10962798 | G27: =IFERROR(VLOOKUP($M27, LostPackets!$D$2:$L$200, 4, 0),0) -> 0.10463 | H27: =IFERROR(VLOOKUP($M27, LostPackets!$D$2:$L$200, 5, 0),0)*2.262 /SQRT(10) -> 0.098175914 | I27: =IFERROR(VLOOKUP($M27, LostPackets!$D$2:$L$200, 6, 0),0) -> 0.0625 | J27: =IFERROR(VLOOKUP($M27, LostPackets!$D$2:$L$200, 7, 0),0)*2.262 /SQRT(10) -> 0.078791089 | K27: =IFERROR(VLOOKUP($M27, LostPackets!$D$2:$L$200, 8, 0),0) -> 0.04464 | L27: =IFERROR(VLOOKUP($M27, LostPackets!$D$2:$L$200, 9, 0),0)*2.262 /SQRT(10) -> 0.069406258 | M27: =D27&A27&B27 -> NO SDWN25670
A28: 256 | B28: 70 | D28: SDWN EDCA | E28: =IFERROR(VLOOKUP($M28, LostPackets!$D$2:$L$200, 2, 0),0) -> 0.15093 | F28: =IFERROR(VLOOKUP($M28, LostPackets!$D$2:$L$200, 3, 0),0)*2.262 /SQRT(10) -> 0.11077247 | G28: =IFERROR(VLOOKUP($M28, LostPackets!$D$2:$L$200, 4, 0),0) -> 0.08473 | H28: =IFERROR(VLOOKUP($M28, LostPackets!$D$2:$L$200, 5, 0),0)*2.262 /SQRT(10) -> 0.087639439 | I28: =IFERROR(VLOOKUP($M28, LostPackets!$D$2:$L$200, 6, 0),0) -> 0.0496 | J28: =IFERROR(VLOOKUP($M28, LostPackets!$D$2:$L$200, 7, 0),0)*2.262 /SQRT(10) -> 0.067038591 | K28: =IFERROR(VLOOKUP($M28, LostPackets!$D$2:$L$200, 8, 0),0) -> 0.03649 | L28: =IFERROR(VLOOKUP($M28, LostPackets!$D$2:$L$200, 9, 0),0)*2.262 /SQRT(10) -> 0.058648038 | M28: =D28&A28&B28 -> SDWN EDCA25670
A29: 256 | B29: 70 | D29: SDWN MOD | E29: =IFERROR(VLOOKUP($M29, LostPackets!$D$2:$L$200, 2, 0),0) -> 0.09032 | F29: =IFERROR(VLOOKUP($M29, LostPackets!$D$2:$L$200, 3, 0),0)*2.262 /SQRT(10) -> 0.064527863 | G29: =IFERROR(VLOOKUP($M29, LostPackets!$D$2:$L$200, 4, 0),0) -> 0.02793 | H29: =IFERROR(VLOOKUP($M29, LostPackets!$D$2:$L$200, 5, 0),0)*2.262 /SQRT(10) -> 0.044527874 | I29: =IFERROR(VLOOKUP($M29, LostPackets!$D$2:$L$200, 6, 0),0) -> 0 | J29: =IFERROR(VLOOKUP($M29, LostPackets!$D$2:$L$200, 7, 0),0)*2.262 /SQRT(10) -> 0 | K29: =IFERROR(VLOOKUP($M29, LostPackets!$D$2:$L$200, 8, 0),0) -> 0 | L29: =IFERROR(VLOOKUP($M29, LostPackets!$D$2:$L$200, 9, 0),0)*2.262 /SQRT(10) -> 0 | M29: =D29&A29&B29 -> SDWN MOD25670
A30: 256 | B30: 70 | D30: SDWN IA | E30: =IFERROR(VLOOKUP($M30, LostPackets!$D$2:$L$200, 2, 0),0) -> 0.10463 | F30: =IFERROR(VLOOKUP($M30, LostPackets!$D$2:$L$200, 3, 0),0)*2.262 /SQRT(10) -> 0.075429145 | G30: =IFERROR(VLOOKUP($M30, LostPackets!$D$2:$L$200, 4, 0),0) -> 0.06389 | H30: =IFERROR(VLOOKUP($M30, LostPackets!$D$2:$L$200, 5, 0),0)*2.262 /SQRT(10) -> 0.063175932 | I30: =IFERROR(VLOOKUP($M30, LostPackets!$D$2:$L$200, 6, 0),0) -> 0.01765 | J30: =IFERROR(VLOOKUP($M30, LostPackets!$D$2:$L$200, 7, 0),0)*2.262 /SQRT(10) -> 0.036680954 | K30: =IFERROR(VLOOKUP($M30, LostPackets!$D$2:$L$200, 8, 0),0) -> 0.00588 | L30: =IFERROR(VLOOKUP($M30, LostPackets!$D$2:$L$200, 9, 0),0)*2.262 /SQRT(10) -> 0.021995697 | M30: =D30&A30&B30 -> SDWN IA25670
A31: 256 | B31: 80 | C31: \multirow{4}{*}{80} | D31: NO SDWN | E31: =IFERROR(VLOOKUP($M31, LostPackets!$D$2:$L$200, 2, 0),0) -> 0.21633 | F31: =IFERROR(VLOOKUP($M31, LostPackets!$D$2:$L$200, 3, 0),0)*2.262 /SQRT(10) -> 0.13218877 | G31: =IFERROR(VLOOKUP($M31, LostPackets!$D$2:$L$200, 4, 0),0) -> 0.095 | H31: =IFERROR(VLOOKUP($M31, LostPackets!$D$2:$L$200, 5, 0),0)*2.262 /SQRT(10) -> 0.091967048 | I31: =IFERROR(VLOOKUP($M31, LostPackets!$D$2:$L$200, 6, 0),0) -> 0.06937 | J31: =IFERROR(VLOOKUP($M31, LostPackets!$D$2:$L$200, 7, 0),0)*2.262 /SQRT(10) -> 0.080522132 | K31: =IFERROR(VLOOKUP($M31, LostPackets!$D$2:$L$200, 8, 0),0) -> 0.0425 | L31: =IFERROR(VLOOKUP($M31, LostPackets!$D$2:$L$200, 9, 0),0)*2.262 /SQRT(10) -> 0.061945604 | M31: =D31&A31&B31 -> NO SDWN25680
A32: 256 | B32: 80 | D32: SDWN EDCA | E32: =IFERROR(VLOOKUP($M32, LostPackets!$D$2:$L$200, 2, 0),0) -> 0.17755 | F32: =IFERROR(VLOOKUP($M32, LostPackets!$D$2:$L$200, 3, 0),0)*2.262 /SQRT(10) -> 0.12193127 | G32: =IFERROR(VLOOKUP($M32, LostPackets!$D$2:$L$200, 4, 0),0) -> 0.10917 | H32: =IFERROR(VLOOKUP($M32, LostPackets!$D$2:$L$200, 5, 0),0)*2.262 /SQRT(10) -> 0.10158078 | I32: =IFERROR(VLOOKUP($M32, LostPackets!$D$2:$L$200, 6, 0),0) -> 0.08124 | J32: =IFERROR(VLOOKUP($M32, LostPackets!$D$2:$L$200, 7, 0),0)*2.262 /SQRT(10) -> 0.084391944 | K32: =IFERROR(VLOOKUP($M32, LostPackets!$D$2:$L$200, 8, 0),0) -> 0.03872 | L32: =IFERROR(VLOOKUP($M32, LostPackets!$D$2:$L$200, 9, 0),0)*2.262 /SQRT(10) -> 0.063011412 | M32: =D32&A32&B32 -> SDWN EDCA25680
A33: 256 | B33: 80 | D33: SDWN MOD | E33: =IFERROR(VLOOKUP($M33, LostPackets!$D$2:$L$200, 2, 0),0) -> 0.09583 | F33: =IFERROR(VLOOKUP($M33, LostPackets!$D$2:$L$200, 3, 0),0)*2.262 /SQRT(10) -> 0.064685231 | G33: =IFERROR(VLOOKUP($M33, LostPackets!$D$2:$L$200, 4, 0),0) -> 0.02189 | H33: =IFERROR(VLOOKUP($M33, LostPackets!$D$2:$L$200, 5, 0),0)*2.262 /SQRT(10) -> 0.040264643 | I33: =IFERROR(VLOOKUP($M33, LostPackets!$D$2:$L$200, 6, 0),0) -> 0.00421 | J33: =IFERROR(VLOOKUP($M33, LostPackets!$D$2:$L$200, 7, 0),0)*2.262 /SQRT(10) -> 0.018705283 | K33: =IFERROR(VLOOKUP($M33, LostPackets!$D$2:$L$200, 8, 0),0) -> 0 | L33: =IFERROR(VLOOKUP($M33, LostPackets!$D$2:$L$200, 9, 0),0)*2.262 /SQRT(10) -> 0 | M33: =D33&A33&B33 -> SDWN MOD25680
A34: 256 | B34: 80 | D34: SDWN IA | E34: =IFERROR(VLOOKUP($M34, LostPackets!$D$2:$L$200, 2, 0),0) -> 0.10333 | F34: =IFERROR(VLOOKUP($M34, LostPackets!$D$2:$L$200, 3, 0),0)*2.262 /SQRT(10) -> 0.081344736 | G34: =IFERROR(VLOOKUP($M34, LostPackets!$D$2:$L$200, 4, 0),0) -> 0.0625 | H34: =IFERROR(VLOOKUP($M34, LostPackets!$D$2:$L$200, 5, 0),0)*2.262 /SQRT(10) -> 0.060128724 | I34: =IFERROR(VLOOKUP($M34, LostPackets!$D$2:$L$200, 6, 0),0) -> 0.01917 | J34: =IFERROR(VLOOKUP($M34, LostPackets!$D$2:$L$200, 7, 0),0)*2.262 /SQRT(10) -> 0.038032884 | K34: =IFERROR(VLOOKUP($M34, LostPackets!$D$2:$L$200, 8, 0),0) -> 0 | L34: =IFERROR(VLOOKUP($M34, LostPackets!$D$2:$L$200, 9, 0),0)*2.262 /SQRT(10) -> 0 | M34: =D34&A34&B34 -> SDWN IA25680
A35: 256 | B35: 90 | C35: \multirow{4}{*}{90} | D35: NO SDWN | E35: =IFERROR(VLOOKUP($M35, LostPackets!$D$2:$L$200, 2, 0),0) -> 0.2076 | F35: =IFERROR(VLOOKUP($M35, LostPackets!$D$2:$L$200, 3, 0),0)*2.262 /SQRT(10) -> 0.13635186 | G35: =IFERROR(VLOOKUP($M35, LostPackets!$D$2:$L$200, 4, 0),0) -> 0.12849 | H35: =IFERROR(VLOOKUP($M35, LostPackets!$D$2:$L$200, 5, 0),0)*2.262 /SQRT(10) -> 0.11023599 | I35: =IFERROR(VLOOKUP($M35, LostPackets!$D$2:$L$200, 6, 0),0) -> 0.07002 | J35: =IFERROR(VLOOKUP($M35, LostPackets!$D$2:$L$200, 7, 0),0)*2.262 /SQRT(10) -> 0.081101531 | K35: =IFERROR(VLOOKUP($M35, LostPackets!$D$2:$L$200, 8, 0),0) -> 0.04015 | L35: =IFERROR(VLOOKUP($M35, LostPackets!$D$2:$L$200, 9, 0),0)*2.262 /SQRT(10) -> 0.063404831 | M35: =D35&A35&B35 -> NO SDWN25690
